Workbook

Sheet README
A1: SHP 2026 New Patients — Performance to Budget
A2: Built 2026-07-30 from the 2026 budget workbook and three EMR new-patient exports. All grey/black cells are formulas.
A4: What this workbook does
A5: Compares actual new patients (first appointment date) against the 2026 budget, by month and by service line,
A6: for January through July 2026, and sets an August 2026 scorecard with targets, pacing and thresholds.
A8: Source files
A9: 2026_New_Patients_by_Channel_Budget_7.29.xlsx -> tab "New Patients Breakout" (budget; provided 2026-07-29)
A10: data__20260730T134900.xlsx -> EMR export, first appt dates 2026-01-02 to 2026-03-31
A11: data__20260730T134956.xlsx -> EMR export, first appt dates 2026-04-01 to 2026-06-30
A12: data__20260730T135432.xlsx -> EMR export, first appt dates 2026-07-01 to 2026-07-31
A13: GA4 property 370514163 ("SHP - New Site - GA4") via the Google Analytics MCP, pulled 2026-07-30.
A15: Method and key assumptions
... A48: here proves what caused a change. The Digital Context tab is directional only.

Sheet Actuals
A1: Actual New Patients by Service Line — 2026
A2: Counted by first appointment date. Blue cells are the inputs; replace them each month.
A4: Service Line | B4: Jan-26 | C4: Feb-26 | D4: Mar-26 | E4: Apr-26 | F4: May-26 | G4: Jun-26 | H4: Jul-26 | I4: Aug-26 | J4: Sep-26 | K4: Oct-26 | L4: Nov-26 | M4: Dec-26 | N4: YTD Jan-Jul
A5: Ortho | B5: 450 | C5: 400 | D5: 406 | E5: 492 | F5: 461 | G5: 496 | H5: 534 | N5: =SUM(B5:H5)
A6: Spine | B6: 185 | C6: 163 | D6: 243 | E6: 217 | F6: 216 | G6: 247 | H6: 199 | N6: =SUM(B6:H6)
A7: Pain & Other | B7: 47 | C7: 34 | D7: 30 | E7: 59 | F7: 38 | G7: 64 | H7: 57 | N7: =SUM(B7:H7)
A8: Foot | B8: 124 | C8: 131 | D8: 128 | E8: 176 | F8: 174 | G8: 196 | H8: 228 | N8: =SUM(B8:H8)
A9: Hand | B9: 95 | C9: 97 | D9: 136 | E9: 102 | F9: 137 | G9: 122 | H9: 137 | N9: =SUM(B9:H9)
A10: Primary Care | B10: 53 | C10: 35 | D10: 36 | E10: 21 | F10: 14 | G10: 13 | H10: 16 | N10: =SUM(B10:H10)
A11: PA / Mid-Level | B11: 10 | C11: 6 | D11: 4 | E11: 6 | F11: 7 | G11: 5 | H11: 7 | N11: =SUM(B11:H11)
A12: Total | B12: =SUM(B5:B11) | C12: =SUM(C5:C11) | D12: =SUM(D5:D11) | E12: =SUM(E5:E11) | F12: =SUM(F5:F11) | G12: =SUM(G5:G11) | H12: =SUM(H5:H11) | I12: =SUM(I5:I11) | ... N12: =SUM(N5:N11)
A14: Operating days | B14: 21 | C14: 20 | D14: 22 | E14: 22 | F14: 20 | G14: 22 | H14: 22 | I14: 21 | J14: 21 | K14: 22 | L14: 21 | M14: 20
A15: New patients per operating day | B15: =B12/B14 | C15: =C12/C14 | D15: =D12/D14 | E15: =E12/E14 | F15: =F12/F14 | G15: =G12/G14 | H15: =H12/H14
A17: Jan-Jul operating days are observed: days with 10 or more new patients in the EMR export.
A18: Aug-Dec operating days are weekdays less standard US holidays (Labor Day, Thanksgiving x2, Christmas Eve/Day). Adjust for your actual clinic calendar.
A19: PA / Mid-Level is a separate service line in the EMR export. The budget allocates PA volume into the six clinical lines — see Perf to Budget.

Sheet Budget
A1: 2026 New Patient Budget by Service Line
A2: Source: 2026_New_Patients_by_Channel_Budget_7.29.xlsx, tab "New Patients Breakout". Values carried at full precision.
A4: Budget — PA allocated into service lines (used for all variance reporting)
A5: Service Line | B5: Jan-26 | C5: Feb-26 | D5: Mar-26 | E5: Apr-26 | F5: May-26 | G5: Jun-26 | H5: Jul-26 | I5: Aug-26 | J5: Sep-26 | K5: Oct-26 | L5: Nov-26 | M5: Dec-26 | N5: FY 2026
A6: Ortho | B6: 496.14106 | C6: 451.62955 | D6: 547.52815 | E6: 588.73017 | F6: 458.78485 | G6: 559.88033 | H6: 522.77061 | I6: 494.23532 | J6: 555.60206 | K6: 521.06033 | L6: 392.51351 | M6: 426.82997 | N6: =SUM(B6:M6)
A7: Spine | B7: 190.40501 | C7: 180.43311 | D7: 309.08847 | E7: 308.69747 | F7: 290.5116 | G7: 327.13314 | H7: 356.43451 | I7: 337.98604 | J7: 328.11145 | K7: 361.99981 | L7: 317.95787 | M7: 315.44519 | N7: =SUM(B7:M7)
A8: Pain | B8: 76.162005 | C8: 72.173245 | D8: 79.479893 | E8: 80.48184 | F8: 74.862604 | G8: 78.297441 | H8: 85.996896 | I8: 77.570566 | J8: 76.559339 | K8: 80.078746 | L8: 73.459232 | M8: 79.405168 | N8: =SUM(B8:M8)
A9: Foot | B9: 177.34867 | C9: 200.11672 | D9: 222.98525 | E9: 239.24054 | F9: 216.76635 | G9: 224.16665 | H9: 234.22839 | I9: 218.30574 | J9: 215.45985 | K9: 250.10896 | L9: 185.29269 | M9: 184.91614 | N9: =SUM(B9:M9)
A10: Hand | B10: 95.697255 | C10: 97.143292 | D10: 99.043658 | E10: 99.907549 | F10: 102.26682 | G10: 99.149545 | H10: 105.64686 | I10: 104.49793 | J10: 104.16703 | K10: 105.52271 | L10: 106.52327 | M10: 106.73827 | N10: =SUM(B10:M10)
A11: PCP | B11: 27.200716 | C11: 27.33835 | D11: 27.597185 | E11: 27.562274 | F11: 27.933807 | G11: 26.814192 | H11: 28.288453 | I11: 27.703774 | J11: 27.342621 | K11: 27.424228 | L11: 27.410161 | M11: 27.193551 | N11: =SUM(B11:M11)
A12: Total | B12: =SUM(B6:B11) | C12: =SUM(C6:C11) | D12: =SUM(D6:D11) | E12: =SUM(E6:E11) | F12: =SUM(F6:F11) | G12: =SUM(G6:G11) | H12: =SUM(H6:H11) | I12: =SUM(I6:I11) | ... N12: =SUM(N6:N11)
A14: Raw budget inputs — before PA allocation (reference only)
A15: Service Line | B15: Jan-26 | C15: Feb-26 | D15: Mar-26 | E15: Apr-26 | F15: May-26 | G15: Jun-26 | H15: Jul-26 | I15: Aug-26 | J15: Sep-26 | K15: Oct-26 | L15: Nov-26 | M15: Dec-26 | N15: FY 2026
A16: Ortho | B16: 456 | C16: 413 | D16: 496 | E16: 534 | F16: 410.6 | G16: 522 | H16: 462 | I16: 446 | J16: 508 | K16: 475 | L16: 358 | M16: 392.4 | N16: =SUM(B16:M16)
A17: Spine | B17: 175 | C17: 165 | D17: 280 | E17: 280 | F17: 260 | G17: 305 | H17: 315 | I17: 305 | J17: 300 | K17: 330 | L17: 290 | M17: 290 | N17: =SUM(B17:M17)
A18: Pain | B18: 70 | C18: 66 | D18: 72 | E18: 73 | F18: 67 | G18: 73 | H18: 76 | I18: 70 | J18: 70 | K18: 73 | L18: 67 | M18: 73 | N18: =SUM(B18:M18)
A19: Foot | B19: 163 | C19: 183 | D19: 202 | E19: 217 | F19: 194 | G19: 209 | H19: 207 | I19: 197 | J19: 197 | K19: 228 | L19: 169 | M19: 170 | N19: =SUM(B19:M19)
A20: Hand | B20: 87.95472 | C20: 88.834267 | D20: 89.72261 | E20: 90.619836 | F20: 91.526034 | G20: 92.441295 | H20: 93.365708 | I20: 94.299365 | J20: 95.242358 | K20: 96.194782 | L20: 97.15673 | M20: 98.128297 | N20: =SUM(B20:M20)
A21: PCP | B21: 25 | C21: 25 | D21: 25 | E21: 25 | F21: 25 | G21: 25 | H21: 25 | I21: 25 | J21: 25 | K21: 25 | L21: 25 | M21: 25 | N21: =SUM(B21:M21)
A22: PA | B22: 86 | C22: 88 | D22: 121 | E22: 125 | F22: 123 | G22: 89 | H22: 155 | I22: 123 | J22: 112 | K22: 119 | L22: 97 | M22: 92 | N22: =SUM(B22:M22)
A23: Total | B23: =SUM(B16:B22) | C23: =SUM(C16:C22) | D23: =SUM(D16:D22) | E23: =SUM(E16:E22) | F23: =SUM(F16:F22) | G23: =SUM(G16:G22) | H23: =SUM(H16:H22) | I23: =SUM(I16:I22) | ... N23: =SUM(N16:N22)
A25: Budget channel split
A26: Channel | B26: Jan-26 | C26: Feb-26 | D26: Mar-26 | E26: Apr-26 | F26: May-26 | G26: Jun-26 | H26: Jul-26 | I26: Aug-26 | J26: Sep-26 | K26: Oct-26 | L26: Nov-26 | M26: Dec-26 | N26: FY 2026
A27: B2C + Natural | B27: 835.31234 | C27: 808.49912 | D27: 1010.3723 | E27: 1056.6561 | F27: 920.31768 | G27: 1033.7264 | H27: 1047.8121 | I27: 990.39365 | J27: 1027.2833 | K27: 1057.8937 | L27: 866.90468 | M27: 896.27276 | N27: =SUM(B27:M27)
A28: B2B (referral / liaison) | B28: 227.64238 | C28: 220.33515 | D28: 275.35035 | E28: 287.96378 | F28: 250.80835 | G28: 281.71491 | H28: 285.5536 | I28: 269.90571 | J28: 279.95902 | K28: 288.30107 | L28: 236.25205 | M28: 244.25554 | N28: =SUM(B28:M28)
A29: B2B share of new patients | B29: =B28/(B27+B28) | C29: =C28/(C27+C28) | D29: =D28/(D27+D28) | E29: =E28/(E27+E28) | F29: =F28/(F27+F28) | G29: =G28/(G27+G28) | H29: =H28/(H27+H28) | I29: =I28/(I27+I28) | ... N29: =N28/(N27+N28)
A31: The budget assumes 21.4% of new patients arrive through B2B / physician referral and 78.6% through B2C and natural demand.
A32: The EMR export carries no source field, so actuals cannot yet be split B2C vs B2B. Closing that gap is the single highest-value data fix — see Trends.

Sheet Perf to Budget
A1: Performance to Budget — January through July 2026
A2: Actual less budget, by service line and month. Green cells link to the Actuals and Budget tabs.
A4: Actual new patients (PA / Mid-Level allocated pro rata into the six lines)
A5: Service Line | B5: Jan-26 | C5: Feb-26 | D5: Mar-26 | E5: Apr-26 | F5: May-26 | G5: Jun-26 | H5: Jul-26 | I5: YTD
A6: Ortho | B6: =Actuals!B5*(1+Actuals!B$11/(Actuals!B$12-Actuals!B$11)) | C6: =Actuals!C5*(1+Actuals!C$11/(Actuals!C$12-Actuals!C$11)) | D6: =Actuals!D5*(1+Actuals!D$11/(Actuals!D$12-Actuals!D$11)) | E6: =Actuals!E5*(1+Actuals!E$11/(Actuals!E$12-Actuals!E$11)) | F6: =Actuals!F5*(1+Actuals!F$11/(Actuals!F$12-Actuals!F$11)) | G6: =Actuals!G5*(1+Actuals!G$11/(Actuals!G$12-Actuals!G$11)) | H6: =Actuals!H5*(1+Actuals!H$11/(Actuals!H$12-Actuals!H$11)) | I6: =SUM(B6:H6)
A7: Spine | B7: =Actuals!B6*(1+Actuals!B$11/(Actuals!B$12-Actuals!B$11)) | C7: =Actuals!C6*(1+Actuals!C$11/(Actuals!C$12-Actuals!C$11)) | D7: =Actuals!D6*(1+Actuals!D$11/(Actuals!D$12-Actuals!D$11)) | E7: =Actuals!E6*(1+Actuals!E$11/(Actuals!E$12-Actuals!E$11)) | F7: =Actuals!F6*(1+Actuals!F$11/(Actuals!F$12-Actuals!F$11)) | G7: =Actuals!G6*(1+Actuals!G$11/(Actuals!G$12-Actuals!G$11)) | H7: =Actuals!H6*(1+Actuals!H$11/(Actuals!H$12-Actuals!H$11)) | I7: =SUM(B7:H7)
A8: Pain | B8: =Actuals!B7*(1+Actuals!B$11/(Actuals!B$12-Actuals!B$11)) | C8: =Actuals!C7*(1+Actuals!C$11/(Actuals!C$12-Actuals!C$11)) | D8: =Actuals!D7*(1+Actuals!D$11/(Actuals!D$12-Actuals!D$11)) | E8: =Actuals!E7*(1+Actuals!E$11/(Actuals!E$12-Actuals!E$11)) | F8: =Actuals!F7*(1+Actuals!F$11/(Actuals!F$12-Actuals!F$11)) | G8: =Actuals!G7*(1+Actuals!G$11/(Actuals!G$12-Actuals!G$11)) | H8: =Actuals!H7*(1+Actuals!H$11/(Actuals!H$12-Actuals!H$11)) | I8: =SUM(B8:H8)
A9: Foot | B9: =Actuals!B8*(1+Actuals!B$11/(Actuals!B$12-Actuals!B$11)) | C9: =Actuals!C8*(1+Actuals!C$11/(Actuals!C$12-Actuals!C$11)) | D9: =Actuals!D8*(1+Actuals!D$11/(Actuals!D$12-Actuals!D$11)) | E9: =Actuals!E8*(1+Actuals!E$11/(Actuals!E$12-Actuals!E$11)) | F9: =Actuals!F8*(1+Actuals!F$11/(Actuals!F$12-Actuals!F$11)) | G9: =Actuals!G8*(1+Actuals!G$11/(Actuals!G$12-Actuals!G$11)) | H9: =Actuals!H8*(1+Actuals!H$11/(Actuals!H$12-Actuals!H$11)) | I9: =SUM(B9:H9)
A10: Hand | B10: =Actuals!B9*(1+Actuals!B$11/(Actuals!B$12-Actuals!B$11)) | C10: =Actuals!C9*(1+Actuals!C$11/(Actuals!C$12-Actuals!C$11)) | D10: =Actuals!D9*(1+Actuals!D$11/(Actuals!D$12-Actuals!D$11)) | E10: =Actuals!E9*(1+Actuals!E$11/(Actuals!E$12-Actuals!E$11)) | F10: =Actuals!F9*(1+Actuals!F$11/(Actuals!F$12-Actuals!F$11)) | G10: =Actuals!G9*(1+Actuals!G$11/(Actuals!G$12-Actuals!G$11)) | H10: =Actuals!H9*(1+Actuals!H$11/(Actuals!H$12-Actuals!H$11)) | I10: =SUM(B10:H10)
A11: PCP | B11: =Actuals!B10*(1+Actuals!B$11/(Actuals!B$12-Actuals!B$11)) | C11: =Actuals!C10*(1+Actuals!C$11/(Actuals!C$12-Actuals!C$11)) | D11: =Actuals!D10*(1+Actuals!D$11/(Actuals!D$12-Actuals!D$11)) | E11: =Actuals!E10*(1+Actuals!E$11/(Actuals!E$12-Actuals!E$11)) | F11: =Actuals!F10*(1+Actuals!F$11/(Actuals!F$12-Actuals!F$11)) | G11: =Actuals!G10*(1+Actuals!G$11/(Actuals!G$12-Actuals!G$11)) | H11: =Actuals!H10*(1+Actuals!H$11/(Actuals!H$12-Actuals!H$11)) | I11: =SUM(B11:H11)
A12: Total | B12: =SUM(B6:B11) | C12: =SUM(C6:C11) | D12: =SUM(D6:D11) | E12: =SUM(E6:E11) | F12: =SUM(F6:F11) | G12: =SUM(G6:G11) | H12: =SUM(H6:H11) | I12: =SUM(I6:I11)
A14: Budget
A15: Service Line | B15: Jan-26 | C15: Feb-26 | D15: Mar-26 | E15: Apr-26 | F15: May-26 | G15: Jun-26 | H15: Jul-26 | I15: YTD
A16: Ortho | B16: =Budget!B6 | C16: =Budget!C6 | D16: =Budget!D6 | E16: =Budget!E6 | F16: =Budget!F6 | G16: =Budget!G6 | H16: =Budget!H6 | I16: =SUM(B16:H16)
A17: Spine | B17: =Budget!B7 | C17: =Budget!C7 | D17: =Budget!D7 | E17: =Budget!E7 | F17: =Budget!F7 | G17: =Budget!G7 | H17: =Budget!H7 | I17: =SUM(B17:H17)
A18: Pain | B18: =Budget!B8 | C18: =Budget!C8 | D18: =Budget!D8 | E18: =Budget!E8 | F18: =Budget!F8 | G18: =Budget!G8 | H18: =Budget!H8 | I18: =SUM(B18:H18)
A19: Foot | B19: =Budget!B9 | C19: =Budget!C9 | D19: =Budget!D9 | E19: =Budget!E9 | F19: =Budget!F9 | G19: =Budget!G9 | H19: =Budget!H9 | I19: =SUM(B19:H19)
A20: Hand | B20: =Budget!B10 | C20: =Budget!C10 | D20: =Budget!D10 | E20: =Budget!E10 | F20: =Budget!F10 | G20: =Budget!G10 | H20: =Budget!H10 | I20: =SUM(B20:H20)
A21: PCP | B21: =Budget!B11 | C21: =Budget!C11 | D21: =Budget!D11 | E21: =Budget!E11 | F21: =Budget!F11 | G21: =Budget!G11 | H21: =Budget!H11 | I21: =SUM(B21:H21)
A22: Total | B22: =SUM(B16:B21) | C22: =SUM(C16:C21) | D22: =SUM(D16:D21) | E22: =SUM(E16:E21) | F22: =SUM(F16:F21) | G22: =SUM(G16:G21) | H22: =SUM(H16:H21) | I22: =SUM(I16:I21)
A24: Variance — actual less budget (negative = behind)
A25: Service Line | B25: Jan-26 | C25: Feb-26 | D25: Mar-26 | E25: Apr-26 | F25: May-26 | G25: Jun-26 | H25: Jul-26 | I25: YTD
A26: Ortho | B26: =B6-B16 | C26: =C6-C16 | D26: =D6-D16 | E26: =E6-E16 | F26: =F6-F16 | G26: =G6-G16 | H26: =H6-H16 | I26: =I6-I16
A27: Spine | B27: =B7-B17 | C27: =C7-C17 | D27: =D7-D17 | E27: =E7-E17 | F27: =F7-F17 | G27: =G7-G17 | H27: =H7-H17 | I27: =I7-I17
A28: Pain | B28: =B8-B18 | C28: =C8-C18 | D28: =D8-D18 | E28: =E8-E18 | F28: =F8-F18 | G28: =G8-G18 | H28: =H8-H18 | I28: =I8-I18
A29: Foot | B29: =B9-B19 | C29: =C9-C19 | D29: =D9-D19 | E29: =E9-E19 | F29: =F9-F19 | G29: =G9-G19 | H29: =H9-H19 | I29: =I9-I19
A30: Hand | B30: =B10-B20 | C30: =C10-C20 | D30: =D10-D20 | E30: =E10-E20 | F30: =F10-F20 | G30: =G10-G20 | H30: =H10-H20 | I30: =I10-I20
A31: PCP | B31: =B11-B21 | C31: =C11-C21 | D31: =D11-D21 | E31: =E11-E21 | F31: =F11-F21 | G31: =G11-G21 | H31: =H11-H21 | I31: =I11-I21
A32: Total | B32: =B12-B22 | C32: =C12-C22 | D32: =D12-D22 | E32: =E12-E22 | F32: =F12-F22 | G32: =G12-G22 | H32: =H12-H22 | I32: =I12-I22
A34: Attainment — actual as a percent of budget
A35: Service Line | B35: Jan-26 | C35: Feb-26 | D35: Mar-26 | E35: Apr-26 | F35: May-26 | G35: Jun-26 | H35: Jul-26 | I35: YTD
A36: Ortho | B36: =IFERROR(B6/B16,"") | C36: =IFERROR(C6/C16,"") | D36: =IFERROR(D6/D16,"") | E36: =IFERROR(E6/E16,"") | F36: =IFERROR(F6/F16,"") | G36: =IFERROR(G6/G16,"") | H36: =IFERROR(H6/H16,"") | I36: =IFERROR(I6/I16,"")
A37: Spine | B37: =IFERROR(B7/B17,"") | C37: =IFERROR(C7/C17,"") | D37: =IFERROR(D7/D17,"") | E37: =IFERROR(E7/E17,"") | F37: =IFERROR(F7/F17,"") | G37: =IFERROR(G7/G17,"") | H37: =IFERROR(H7/H17,"") | I37: =IFERROR(I7/I17,"")
A38: Pain | B38: =IFERROR(B8/B18,"") | C38: =IFERROR(C8/C18,"") | D38: =IFERROR(D8/D18,"") | E38: =IFERROR(E8/E18,"") | F38: =IFERROR(F8/F18,"") | G38: =IFERROR(G8/G18,"") | H38: =IFERROR(H8/H18,"") | I38: =IFERROR(I8/I18,"")
A39: Foot | B39: =IFERROR(B9/B19,"") | C39: =IFERROR(C9/C19,"") | D39: =IFERROR(D9/D19,"") | E39: =IFERROR(E9/E19,"") | F39: =IFERROR(F9/F19,"") | G39: =IFERROR(G9/G19,"") | H39: =IFERROR(H9/H19,"") | I39: =IFERROR(I9/I19,"")
A40: Hand | B40: =IFERROR(B10/B20,"") | C40: =IFERROR(C10/C20,"") | D40: =IFERROR(D10/D20,"") | E40: =IFERROR(E10/E20,"") | F40: =IFERROR(F10/F20,"") | G40: =IFERROR(G10/G20,"") | H40: =IFERROR(H10/H20,"") | I40: =IFERROR(I10/I20,"")
A41: PCP | B41: =IFERROR(B11/B21,"") | C41: =IFERROR(C11/C21,"") | D41: =IFERROR(D11/D21,"") | E41: =IFERROR(E11/E21,"") | F41: =IFERROR(F11/F21,"") | G41: =IFERROR(G11/G21,"") | H41: =IFERROR(H11/H21,"") | I41: =IFERROR(I11/I21,"")
A42: Total | B42: =IFERROR(B12/B22,"") | C42: =IFERROR(C12/C22,"") | D42: =IFERROR(D12/D22,"") | E42: =IFERROR(E12/E22,"") | F42: =IFERROR(F12/F22,"") | G42: =IFERROR(G12/G22,"") | H42: =IFERROR(H12/H22,"") | I42: =IFERROR(I12/I22,"")
A44: Pro-rata allocation formula: service line actual x (1 + PA volume / non-PA volume). Totals reconcile exactly to the Actuals tab.
A45: Conditional formatting on the attainment block: red below 90% of budget, amber 90-100%, green at or above 100%.

Sheet Trends
A1: Performance Trends — January through July 2026
A2: Volume normalised by operating day, so short months are not penalised.
A4: Total new patients — trend
A5: Measure | B5: Jan-26 | C5: Feb-26 | D5: Mar-26 | E5: Apr-26 | F5: May-26 | G5: Jun-26 | H5: Jul-26 | I5: YTD
A6: Actual new patients | B6: =Actuals!B12 | C6: =Actuals!C12 | D6: =Actuals!D12 | E6: =Actuals!E12 | F6: =Actuals!F12 | G6: =Actuals!G12 | H6: =Actuals!H12 | I6: =SUM(B6:H6)
A7: Budget | B7: ='Perf to Budget'!B22 | C7: ='Perf to Budget'!C22 | D7: ='Perf to Budget'!D22 | E7: ='Perf to Budget'!E22 | F7: ='Perf to Budget'!F22 | G7: ='Perf to Budget'!G22 | H7: ='Perf to Budget'!H22 | I7: =SUM(B7:H7)
A8: Variance to budget | B8: =B6-B7 | C8: =C6-C7 | D8: =D6-D7 | E8: =E6-E7 | F8: =F6-F7 | G8: =G6-G7 | H8: =H6-H7 | I8: =SUM(B8:H8)
A9: Attainment vs budget | B9: =B6/B7 | C9: =C6/C7 | D9: =D6/D7 | E9: =E6/E7 | F9: =F6/F7 | G9: =G6/G7 | H9: =H6/H7 | I9: =I6/I7
A10: Operating days | B10: =Actuals!B14 | C10: =Actuals!C14 | D10: =Actuals!D14 | E10: =Actuals!E14 | F10: =Actuals!F14 | G10: =Actuals!G14 | H10: =Actuals!H14 | I10: =SUM(B10:H10)
A11: Per operating day | B11: =B6/B10 | C11: =C6/C10 | D11: =D6/D10 | E11: =E6/E10 | F11: =F6/F10 | G11: =G6/G10 | H11: =H6/H10 | I11: =I6/I10
A12: Per operating day — MoM | C12: =C11/B11-1 | D12: =D11/C11-1 | E12: =E11/D11-1 | F12: =F11/E11-1 | G12: =G11/F11-1 | H12: =H11/G11-1
A13: Per operating day — index, Jan = 100 | B13: =B11/$B$11*100 | C13: =C11/$B$11*100 | D13: =D11/$B$11*100 | E13: =E11/$B$11*100 | F13: =F11/$B$11*100 | G13: =G11/$B$11*100 | H13: =H11/$B$11*100
A14: 3-month rolling avg per operating day | D14: =AVERAGE(B11:D11) | E14: =AVERAGE(C11:E11) | F14: =AVERAGE(D11:F11) | G14: =AVERAGE(E11:G11) | H14: =AVERAGE(F11:H11)
A17: Service line — volume, half-on-half growth and budget attainment
A18: Service Line | B18: Jan-26 | C18: Feb-26 | D18: Mar-26 | E18: Apr-26 | F18: May-26 | G18: Jun-26 | H18: Jul-26 | I18: YTD | J18: Jan-Mar | K18: Apr-Jul | L18: Apr-Jul vs Jan-Mar per month | M18: YTD attainment
A19: Ortho | B19: ='Perf to Budget'!B6 | C19: ='Perf to Budget'!C6 | D19: ='Perf to Budget'!D6 | E19: ='Perf to Budget'!E6 | F19: ='Perf to Budget'!F6 | G19: ='Perf to Budget'!G6 | H19: ='Perf to Budget'!H6 | I19: =SUM(B19:H19) | J19: =SUM(B19:D19)/3 | K19: =SUM(E19:H19)/4 | L19: =K19/J19-1 | M19: ='Perf to Budget'!I36
A20: Spine | B20: ='Perf to Budget'!B7 | C20: ='Perf to Budget'!C7 | D20: ='Perf to Budget'!D7 | E20: ='Perf to Budget'!E7 | F20: ='Perf to Budget'!F7 | G20: ='Perf to Budget'!G7 | H20: ='Perf to Budget'!H7 | I20: =SUM(B20:H20) | J20: =SUM(B20:D20)/3 | K20: =SUM(E20:H20)/4 | L20: =K20/J20-1 | M20: ='Perf to Budget'!I37
A21: Pain | B21: ='Perf to Budget'!B8 | C21: ='Perf to Budget'!C8 | D21: ='Perf to Budget'!D8 | E21: ='Perf to Budget'!E8 | F21: ='Perf to Budget'!F8 | G21: ='Perf to Budget'!G8 | H21: ='Perf to Budget'!H8 | I21: =SUM(B21:H21) | J21: =SUM(B21:D21)/3 | K21: =SUM(E21:H21)/4 | L21: =K21/J21-1 | M21: ='Perf to Budget'!I38
A22: Foot | B22: ='Perf to Budget'!B9 | C22: ='Perf to Budget'!C9 | D22: ='Perf to Budget'!D9 | E22: ='Perf to Budget'!E9 | F22: ='Perf to Budget'!F9 | G22: ='Perf to Budget'!G9 | H22: ='Perf to Budget'!H9 | I22: =SUM(B22:H22) | J22: =SUM(B22:D22)/3 | K22: =SUM(E22:H22)/4 | L22: =K22/J22-1 | M22: ='Perf to Budget'!I39
A23: Hand | B23: ='Perf to Budget'!B10 | C23: ='Perf to Budget'!C10 | D23: ='Perf to Budget'!D10 | E23: ='Perf to Budget'!E10 | F23: ='Perf to Budget'!F10 | G23: ='Perf to Budget'!G10 | H23: ='Perf to Budget'!H10 | I23: =SUM(B23:H23) | J23: =SUM(B23:D23)/3 | K23: =SUM(E23:H23)/4 | L23: =K23/J23-1 | M23: ='Perf to Budget'!I40
A24: PCP | B24: ='Perf to Budget'!B11 | C24: ='Perf to Budget'!C11 | D24: ='Perf to Budget'!D11 | E24: ='Perf to Budget'!E11 | F24: ='Perf to Budget'!F11 | G24: ='Perf to Budget'!G11 | H24: ='Perf to Budget'!H11 | I24: =SUM(B24:H24) | J24: =SUM(B24:D24)/3 | K24: =SUM(E24:H24)/4 | L24: =K24/J24-1 | M24: ='Perf to Budget'!I41
A25: Total | B25: =SUM(B19:B24) | C25: =SUM(C19:C24) | D25: =SUM(D19:D24) | E25: =SUM(E19:E24) | F25: =SUM(F19:F24) | G25: =SUM(G19:G24) | H25: =SUM(H19:H24) | I25: =SUM(I19:I24) | J25: =SUM(B25:D25)/3 | K25: =SUM(E25:H25)/4 | L25: =K25/J25-1 | M25: ='Perf to Budget'!I42
A28: Full-year 2026 projection at the current run rate
A29: Service Line | B29: Trailing 3-mo per operating day | C29: Aug-Dec operating days | D29: Aug-Dec projected | E29: Jan-Jul actual | F29: FY 2026 projected | G29: FY 2026 budget | H29: Projected variance | I29: Projected attainment
A30: Ortho | B30: =SUM('Perf to Budget'!F6:H6)/SUM(Actuals!$F$14:$H$14) | C30: =SUM(Actuals!$I$14:$M$14) | D30: =B30*C30 | E30: ='Perf to Budget'!I6 | F30: =D30+E30 | G30: =Budget!N6 | H30: =F30-G30 | I30: =F30/G30
A31: Spine | B31: =SUM('Perf to Budget'!F7:H7)/SUM(Actuals!$F$14:$H$14) | C31: =SUM(Actuals!$I$14:$M$14) | D31: =B31*C31 | E31: ='Perf to Budget'!I7 | F31: =D31+E31 | G31: =Budget!N7 | H31: =F31-G31 | I31: =F31/G31
A32: Pain | B32: =SUM('Perf to Budget'!F8:H8)/SUM(Actuals!$F$14:$H$14) | C32: =SUM(Actuals!$I$14:$M$14) | D32: =B32*C32 | E32: ='Perf to Budget'!I8 | F32: =D32+E32 | G32: =Budget!N8 | H32: =F32-G32 | I32: =F32/G32
A33: Foot | B33: =SUM('Perf to Budget'!F9:H9)/SUM(Actuals!$F$14:$H$14) | C33: =SUM(Actuals!$I$14:$M$14) | D33: =B33*C33 | E33: ='Perf to Budget'!I9 | F33: =D33+E33 | G33: =Budget!N9 | H33: =F33-G33 | I33: =F33/G33
A34: Hand | B34: =SUM('Perf to Budget'!F10:H10)/SUM(Actuals!$F$14:$H$14) | C34: =SUM(Actuals!$I$14:$M$14) | D34: =B34*C34 | E34: ='Perf to Budget'!I10 | F34: =D34+E34 | G34: =Budget!N10 | H34: =F34-G34 | I34: =F34/G34
A35: PCP | B35: =SUM('Perf to Budget'!F11:H11)/SUM(Actuals!$F$14:$H$14) | C35: =SUM(Actuals!$I$14:$M$14) | D35: =B35*C35 | E35: ='Perf to Budget'!I11 | F35: =D35+E35 | G35: =Budget!N11 | H35: =F35-G35 | I35: =F35/G35
A36: Total | B36: =SUM(B30:B35) | C36: =C30 | D36: =SUM(D30:D35) | E36: =SUM(E30:E35) | F36: =SUM(F30:F35) | G36: =SUM(G30:G35) | H36: =G36-H36 | I36: =G36/H36
A38: Run rate = May-July actual per operating day, the most recent and most representative three months. It carries no seasonality adjustment.
A39: Aug-Dec operating days come from the Actuals tab, row 14. Correct them for your real clinic calendar and this projection updates.
A40: The budget is materially front-half weighted (Mar, Apr and Jun are the three largest budgeted months); actual volume has instead built steadily through the year.

Sheet Aug Scorecard
A1: August 2026 New Patient Scorecard
A2: Targets, weekly pacing and thresholds. Yellow cells are the choices to own; everything else calculates.
A4: The month at a glance
A5: August budget | C5: Run-rate forecast | E5: Recommended target | G5: Operating days
A6: =Budget!I12 | C6: =E17 | E6: =F17 | G6: =Actuals!I14
A9: Targets by service line
A10: Service Line | B10: August budget | C10: Trailing 3-mo per operating day | D10: Aug operating days | E10: Run-rate forecast | F10: Recommended target | G10: Gap: target less budget | H10: Per operating day needed
A11: Ortho | B11: =Budget!I6 | C11: =SUM('Perf to Budget'!F6:H6)/SUM(Actuals!$F$14:$H$14) | D11: =Actuals!$I$14 | E11: =C11*D11 | F11: =MAX(B11,E11) | G11: =F11-B11 | H11: =F11/D11
A12: Spine | B12: =Budget!I7 | C12: =SUM('Perf to Budget'!F7:H7)/SUM(Actuals!$F$14:$H$14) | D12: =Actuals!$I$14 | E12: =C12*D12 | F12: =MAX(B12,E12) | G12: =F12-B12 | H12: =F12/D12
A13: Pain | B13: =Budget!I8 | C13: =SUM('Perf to Budget'!F8:H8)/SUM(Actuals!$F$14:$H$14) | D13: =Actuals!$I$14 | E13: =C13*D13 | F13: =MAX(B13,E13) | G13: =F13-B13 | H13: =F13/D13
A14: Foot | B14: =Budget!I9 | C14: =SUM('Perf to Budget'!F9:H9)/SUM(Actuals!$F$14:$H$14) | D14: =Actuals!$I$14 | E14: =C14*D14 | F14: =MAX(B14,E14) | G14: =F14-B14 | H14: =F14/D14
A15: Hand | B15: =Budget!I10 | C15: =SUM('Perf to Budget'!F10:H10)/SUM(Actuals!$F$14:$H$14) | D15: =Actuals!$I$14 | E15: =C15*D15 | F15: =MAX(B15,E15) | G15: =F15-B15 | H15: =F15/D15
A16: PCP | B16: =Budget!I11 | C16: =SUM('Perf to Budget'!F11:H11)/SUM(Actuals!$F$14:$H$14) | D16: =Actuals!$I$14 | E16: =C16*D16 | F16: =MAX(B16,E16) | G16: =F16-B16 | H16: =F16/D16
A17: Total | B17: =SUM(B11:B16) | C17: =E17/D17 | D17: =Actuals!$I$14 | E17: =SUM(E11:E16) | F17: =SUM(F11:F16) | G17: =SUM(G11:G16) | H17: =F17/D17
A19: Recommended target = the higher of the August budget and the current run rate, so no line is asked to go backwards from where it is actually running.
A20: Every line except Hand is running below its August budget, so for those five the recommended target IS the budget and the gap column shows what closing it costs.
A22: Threshold — how August gets graded
A23: Grade | B23: Total new patients | C23: Definition
A24: Green — at or above budget | B24: =B17 | C24: Hits the August budget of roughly 1,260 new patients.
A25: Amber — at run rate | B25: =E17 | C25: Holds the May-July run rate. Real progress, still short of budget.
A26: Red — below run rate | B26: =E17*0.95 | C26: More than 5% below the current run rate; the seven-month improvement has stalled.
A28: Weekly pacing — where the month should stand each Friday
A29: Week | B29: Dates | C29: Operating days | D29: Cumulative operating days | E29: Cumulative target | F29: Actual (fill in) | G29: Variance | H29: Status
A30: Week 1 | B30: Aug 3-7 | C30: 5 | D30: =C30 | E30: =$H$17*D30 | G30: =IF(F30="","",F30-E30) | H30: =IF(F30="","",IF(F30>=E30,"On/above pace",IF(F30>=E30*0.95,"Watch","Behind")))
A31: Week 2 | B31: Aug 10-14 | C31: 5 | D31: =D30+C31 | E31: =$H$17*D31 | G31: =IF(F31="","",F31-E31) | H31: =IF(F31="","",IF(F31>=E31,"On/above pace",IF(F31>=E31*0.95,"Watch","Behind")))
A32: Week 3 | B32: Aug 17-21 | C32: 5 | D32: =D31+C32 | E32: =$H$17*D32 | G32: =IF(F32="","",F32-E32) | H32: =IF(F32="","",IF(F32>=E32,"On/above pace",IF(F32>=E32*0.95,"Watch","Behind")))
A33: Week 4 | B33: Aug 24-28 | C33: 5 | D33: =D32+C33 | E33: =$H$17*D33 | G33: =IF(F33="","",F33-E33) | H33: =IF(F33="","",IF(F33>=E33,"On/above pace",IF(F33>=E33*0.95,"Watch","Behind")))
A34: Week 5 | B34: Aug 31 | C34: 1 | D34: =D33+C34 | E34: =$H$17*D34 | G34: =IF(F34="","",F34-E34) | H34: =IF(F34="","",IF(F34>=E34,"On/above pace",IF(F34>=E34*0.95,"Watch","Behind")))
A35: Cumulative target uses the recommended per-operating-day rate from the table above, so pacing and the monthly target can never disagree.
A37: Channel split of the August target
A38: Channel | B38: Budget share | C38: August target | D38: Owner | E38: What has to be true
A39: B2C + natural demand | B39: =Budget!I27/(Budget!I$27+Budget!I$28) | C39: =$F$17*B39 | D39: Marketing | E39: Paid and organic demand hold; the web measurement break is fixed so we can see it.
A40: B2B referral / liaison | B40: =Budget!I28/(Budget!I$27+Budget!I$28) | C40: =$F$17*B40 | D40: Physician liaison | E40: Referral volume from target accounts is captured and attributed in the EMR.
A42: Split is the budget assumption, not measured actuals. The EMR export has no referral-source field, so B2C vs B2B cannot yet be verified.
A44: Leading indicators to watch weekly
A45: Indicator | B45: Source | C45: Why it matters | D45: August watch level | E45: Owner
A46: New patients booked per operating day | B46: EMR export | C46: The single number this scorecard grades. | D46: At or above 53.5 | E46: Practice ops
A47: Website sessions per weekday | B47: GA4 property 370514163 | C47: Leading demand signal — but see the measurement break flagged on Digital Context. | D47: Restore reporting first | E47: Marketing
A48: Paid search sessions | B48: GA4 / Google Ads | C48: Largest single acquisition channel by session volume all year. | D48: Stable or rising | E48: Paid agency
A49: Spine new patients per operating day | B49: EMR export | C49: Worst variance to budget of any line at 74.9% YTD. | D49: At or above 11.2 | E49: Spine service line
...

Sheet Digital Context
A1: Digital Context — GA4, January through July 2026
A2: Directional only. GA4 measures website behaviour; it does not attribute new patients. Read the data-quality flags first.
A4: Data-quality flags — read before using any number on this tab
A5: FLAG 1 GA4 recorded almost no traffic from 18 February to 1 March 2026 (single-digit sessions per day against a ~800/day baseline).
A6: February and early March web numbers are understated by roughly one week of traffic. Patient volume shows no matching dip.
A7: FLAG 2 Sessions step down about 50% from late April onward and stay there — and the drop hits every channel at once, including
A8: Direct and Organic. A simultaneous, uniform, all-channel halving is the signature of a tracking or consent change, not of a
A9: media decision. Verify against Google Search Console clicks and Google Ads before treating any May-July web number as real.
A10: FLAG 3 July key events jump roughly 5x with no matching traffic increase, which means the key-event configuration changed in July.
A11: Conversion counts are not comparable month to month across that break.
A12: Bottom line: patient volume rose every month while measured web sessions fell by half. At least one of those two series is wrong,
A13: and the patient data — counted from the EMR — is the one to trust.
A15: GA4 monthly summary
A16: Month | B16: Sessions | C16: Paid search sessions | D16: Organic search sessions | E16: Direct sessions | F16: Key events | G16: New patients | H16: New patients per 1,000 sessions
A17: Jan-26 | B17: 21619 | C17: 11258 | D17: 6653 | E17: 2482 | F17: 3595 | G17: =Actuals!B12 | H17: =G17/B17*1000
A18: Feb-26 | B18: 10893 | C18: 5717 | D18: 3499 | E18: 1186 | F18: 1774 | G18: =Actuals!C12 | H18: =G18/B18*1000
A19: Mar-26 | B19: 21896 | C19: 12612 | D19: 6163 | E19: 2145 | F19: 3298 | G19: =Actuals!D12 | H19: =G19/B19*1000
A20: Apr-26 | B20: 17967 | C20: 9984 | D20: 5264 | E20: 1717 | F20: 2637 | G20: =Actuals!E12 | H20: =G20/B20*1000
A21: May-26 | B21: 9335 | C21: 5334 | D21: 3027 | E21: 717 | F21: 896 | G21: =Actuals!F12 | H21: =G21/B21*1000
A22: Jun-26 | B22: 10086 | C22: 5937 | D22: 3209 | E22: 669 | F22: 2177 | G22: =Actuals!G12 | H22: =G22/B22*1000
A23: Jul-26 | B23: 8784 | C23: 4973 | D23: 2768 | E23: 594 | F23: 10398 | G23: =Actuals!H12 | H23: =G23/B23*1000
A25: Source: GA4 property 370514163, sessionDefaultChannelGroup by yearMonth, pulled 2026-07-30. July covers 1-29 July only.
A26: "New patients per 1,000 sessions" is a ratio of two independent series, not a conversion rate. It rises sharply after April because
A27: the denominator collapsed, which is exactly what FLAG 2 says not to trust.
