Workbook

Sheet Project Plan
B2: Validate & Finalize Spine Target Accounts by PL
B4: Assigned to: Joel C. · Project owner: Joe MacLean · Source: B2C/B2B Spine Growth Operating Report v4 (B2B appts thru Jul 10; MMC thru Jul 16)
B6: OBJECTIVE
B7: Convert the referral-weighted 848-account workbook (Kristen 180 · Jasmine 310 · Coty 318 · Sean 40) into a PL-validated, field-ready universe with efficient ≤10-stop routes. Counts will decrease/shift as PLs validate.
B9: REALISTIC TIMELINE (adjusted from request — 2 changes, both flagged)
B10: Wed Jul 23 — Review files distributed (this workbook; a day EARLIER than requested Jul 24, so PLs get the weekend). Intro at Thursday Jul 24 debrief.
B11: Tue Jul 29 EOD — PL dispositions complete (~180–320 rows each ≈ 60–90 min/day office time; does NOT displace the Week-1/2 protect sweep already running).
B12: Wed Jul 30 — Joel consolidates dispositions; resolves cross-PL conflicts (one account = one PL).
B13: Thu Jul 31 — Approved universe locked; routes regenerated (scripted — hours, not days); summary to Joe + Kristen.
B14: Mon Aug 3 — Week-3 field execution runs on the CLEANED universe. Sept 30 — execution complete.
B16: THE ONE DECISION THE TIMELINE DEPENDS ON (flag to Joe/Kristen — do not bury):
B17: "Complete outreach by Sept 30" has two modes. A) Protect-first (current build): producers on 14/21-day cycles + ~3 spine days/PL/week → all producers + ~270 of 466 prospects touched; ~200 lowest-score prospects roll to Oct. B) Full-coverage-once: every kept account visited by Sept 30 → needs ~4.5–5 spine days/PL/week from Aug 3 AND thinner producer cadence. Pick A or B explicitly at the Jul 31 sign-off; promising B while resourcing A is how this fails.
... B25: Sean tab: dispositions default to Coty reassignment if Sean′s June-9 activity stall is confirmed (Kristen decides by Jul 24).

Sheet Kristen
A1: Account / Practice | B1: MMC Company ID | C1: Practice Type | D1: Tier | E1: Referral Evidence Band | F1: Target Score | G1: Spine 2026 | H1: Ortho 2026 | I1: Total B2B 2026 | J1: Last Spine Patient | K1: Last Completed Visit | L1: Days Since Visit | M1: Median Visit→Appt Lag | N1: Planned Cadence (d) | O1: Route Day | P1: City | Q1: Full Address | R1: Known Referring Providers | S1: Pre-Flag (auto) | T1: Disposition | U1: Final Practice Type | V1: Final Tier | W1: Spine Opportunity | X1: Employed Spine/Neuro Provider? | Y1: Competitor / Referral Restriction? | Z1: Recommended Cadence (d) | AA1: Removal / Reassignment Reason | AB1: PL Notes
A2: [EXAMPLE] Sample Family Medicine | B2: — | C2: PCP | D2: Tier 2 | E2: Ortho Referrer | F2: 48 | G2: 0 | H2: 3 | I2: 4 | K2: 2026-06-12 | L2: 39 | N2: 21 | O2: K-D03 | P2: Livonia | Q2: 123 Example Rd | R2: Dr. A. Sample (3 ortho) | T2: Keep | U2: PCP | V2: Tier 2 | W2: Medium | X2: No | Y2: No | Z2: 21 | AB2: Solid ortho sender; pitch spine pathway next visit
A3: Mike Morse Law Firm | B3: 2dd4a698-eeec-4552-98ba-d85b130bcc56 | C3: Attorney / Legal | D3: Tier 1 | E3: Repeat Spine Referrer | F3: 98 | G3: 75 | H3: 18 | I3: 94 | J3: 2026-06-24 | K3: 2026-06-24 | L3: 22 | M3: 28 | N3: 14 | O3: K-D01 | P3: Southfield | Q3: 24901 Northwestern Highway, Southfield, Michigan, 48075 | R3: Mike Morse (75 spine)
A4: Hesselberg Chiropractic | B4: 83b9dec3-57ee-4777-b000-fcb1c228e6c7 | C4: Chiropractor | D4: Tier 1 | E4: Repeat Spine Referrer | F4: 97 | G4: 23 | H4: 0 | I4: 23 | J4: 2026-06-17 | K4: 2026-04-27 | L4: 80 | M4: 25 | N4: 14 | O4: K-D05 | P4: Ypsilanti | Q4: 2900 Packard Street, Ypsilanti, Michigan, 48197 | R4: Jason Joseph Hesselberg, DC (22 spine) · Jason Dc Hesselberg (1 spine)
A5: Michigan Auto Law | B5: 8bd62ae0-e836-472d-84f6-a85688fd5524 | C5: Attorney / Legal | D5: Tier 1 | E5: Repeat Spine Referrer | F5: 97 | G5: 10 | H5: 5 | I5: 15 | J5: 2026-06-17 | K5: 2026-04-29 | L5: 78 | M5: 10 | N5: 14 | O5: K-D02 | P5: Farmington Hills | Q5: 30101 Northwestern Hwy, Farmington Hills, Michigan, 48334 | R5: Mi Auto Law (9 spine) · Michigan Auto Law (1 spine) · Kevin Seiferheld (1 ortho)
A6: Park Medical Centers | B6: 92913d4d-edc4-462b-aecf-ef3f54198f09 | C6: PCP | D6: Tier 1 | E6: Repeat Spine Referrer | F6: 99 | G6: 5 | H6: 7 | I6: 12 | J6: 2026-06-02 | K6: 2026-06-30 | L6: 16 | M6: 27.5 | N6: 14 | O6: K-D05 | P6: Livonia | Q6: 38253 Ann Arbor Road, Livonia, Michigan, 48150 | R6: Richard Ozog, DO (4 spine) · Kathryn Marie Poulos, PA (1 spine)
A7: Kajy Law | B7: 3b453978-15f0-429d-ab43-67d84178b21f | C7: Attorney / Legal | D7: Tier 1 | E7: Repeat Spine Referrer | F7: 98 | G7: 5 | H7: 0 | I7: 5 | J7: 2026-05-21 | K7: 2026-06-29 | L7: 17 | M7: 9 | N7: 14 | O7: K-D06 | P7: Southfield | Q7: 18000 W Nine Mile Rd suite 1400, Southfield, Michigan, 48075 | R7: Kajy Law (5 spine)
A8: Henry Ford Primary Care Center - 160 | B8: b6033c7f-ac4e-4957-b3b0-519077da6c8d | C8: PCP | D8: Tier 1 | E8: Repeat Spine Referrer | F8: 97 | G8: 5 | H8: 0 | I8: 6 | J8: 2026-05-20 | K8: 2026-05-08 | L8: 69 | M8: 24.5 | N8: 14 | O8: K-D02 | P8: Farmington Hills | Q8: 30055 Northwestern Hwy, Farmington Hills, Michigan, 48334 | R8: May Antone, MD (4 spine) · Neeran Bajouka, MD (1 spine) · Neeran Yosif Bajouka, MD
A9: DMC PRIMARY AND SPECIALTY CARE WEST BLOOMFIELD | B9: e1df3a06-b408-47d1-8333-8e5c30e7bc97 | C9: PCP | D9: Tier 1 | E9: Repeat Spine Referrer | F9: 97 | G9: 5 | H9: 1 | I9: 6 | J9: 2026-07-08 | K9: 2026-05-07 | L9: 70 | M9: 37 | N9: 14 | O9: K-D07 | P9: WEST BLOOMFIELD | Q9: 6525 W MAPLE RD STE 101E, WEST BLOOMFIELD, MI, 48322 | R9: Mark Aronov, DO (3 spine) · Madhumitha Krishnamoorthy (2 spine)
A10: Stonebrooke Family Physicians | B10: c9013f02-25d6-4df2-96f8-b4f1e9936878 | C10: PCP | D10: Tier 1 | E10: Repeat Spine Referrer | F10: 97 | G10: 5 | H10: 5 | I10: 17 | J10: 2026-07-09 | K10: 2026-06-10 | L10: 36 | M10: 36 | N10: 14 | O10: K-D09 | P10: Rochester Hills | Q10: 2940 Crooks Rd, Rochester Hills, Michigan, 48309 | R10: Ronald Bellisario, MD (2 spine) · Jennifer Haener, DO (1 spine) · Matthew T Ewald, MD (1 spine) · Elizabeth Ryman, PA (1 spine) · Katherine Becker Mitzner, DO (1 ortho) · Stacey Kastl, MD
A11: Ross Law | B11: 86e7413a-57df-4cba-adee-c6d0a8e55b63 | C11: Attorney / Legal | D11: Tier 1 | E11: Repeat Spine Referrer | F11: 96 | G11: 5 | H11: 2 | I11: 7 | J11: 2026-06-22 | K11: 2026-05-29 | L11: 48 | M11: 14 | N11: 14 | O11: K-D03 | P11: Southfield | Q11: 29200 Northwestern Hwy, Southfield, Michigan, 48034 | R11: Ross Law (5 spine)
A12: Applebaum & Stone | B12: 89b27066-bd8f-45eb-b2ec-e3196a89a16c | C12: Attorney / Legal | D12: Tier 1 | E12: Repeat Spine Referrer | F12: 95 | G12: 5 | H12: 2 | I12: 7 | J12: 2026-06-26 | K12: 2026-03-16 | L12: 122 | M12: 58 | N12: 14 | O12: K-D10 | P12: Southfield | Q12: 26777 Central Park Blvd suite 300, Southfield, Michigan, 48076 | R12: Applebaum and Stone (5 spine)
A13: Vanstone Injury Law | B13: 5ffbe2ff-83ec-4e24-8d4f-4071334a9c5c | C13: Attorney / Legal | D13: Tier 1 | E13: Repeat Spine Referrer | F13: 94 | G13: 5 | H13: 0 | I13: 5 | J13: 2026-05-07 | K13: 2026-02-27 | L13: 139 | M13: 10 | N13: 14 | O13: K-D11 | Q13: 7031 Orchard Lake Rd West Bloomfield Township, Michigan, 48322 | R13: Vanstone Law (3 spine) · Vanstone (2 spine)
A14: DMC Orthopedics - Commerce Township | B14: 568c9052-985c-48fa-b5bc-44baafba3dea | C14: Orthopedic | D14: Tier 1 | E14: Repeat Spine Referrer | F14: 91 | G14: 3 | H14: 0 | I14: 3 | J14: 2026-07-06 | K14: 2026-07-07 | L14: 9 | M14: 0 | N14: 14 | O14: K-D07 | Q14: 1 William Carls Drive, Michigan, 48382 | R14: Mark Mackey, MD (1 spine)
A15: Hermann Banks MD PC | B15: 31597599-5a74-4f7a-8cb0-0ebbb4b41303 | C15: Neurology | D15: Tier 1 | E15: Repeat Spine Referrer | F15: 91 | G15: 3 | H15: 0 | I15: 3 | J15: 2026-06-29 | K15: 2026-06-29 | L15: 17 | M15: 26 | N15: 14 | O15: K-D08 | P15: Livonia | Q15: 14700 Farmington Rd, Livonia, Michigan, 48154 | R15: Hermann Darwin Banks (2 spine) · Hermann Banks, MD (1 spine)
A16: Levine Clinic of Chiropractic | B16: e19f7675-d86b-445b-ad8d-c06409bfde92 | C16: Chiropractor | D16: Tier 1 | E16: Repeat Spine Referrer | F16: 90 | G16: 3 | H16: 1 | I16: 5 | J16: 2026-06-01 | K16: 2026-05-08 | L16: 69 | M16: 9 | N16: 14 | O16: K-D03 | P16: Farmington Hills | Q16: 31390 Northwestern Hwy., Ste C, Farmington Hills, Michigan, 48334 | R16: Richard Levine, DC (3 spine)
A17: Beaumont Medical Center - Redford | B17: 03095e36-e586-4709-8cd8-440a98b9bcd7 | C17: PCP | D17: Tier 1 | E17: Repeat Spine Referrer | F17: 89 | G17: 3 | H17: 20 | I17: 23 | J17: 2026-06-12 | K17: 2026-05-01 | L17: 76 | M17: 33 | N17: 14 | O17: K-D01 | P17: Redford Charter Township | Q17: 15540 Beech Daly, Redford Charter Township, Michigan, 48239 | R17: Liza Weathersby, MD (2 spine) · Britani Alyce Marshall, MD (1 spine) · Britani Marshall, MD (1 ortho)
A18: Lifetime Family Care | B18: b70053c3-f0fd-41de-9386-95fcc448a738 | C18: PCP | D18: Tier 1 | E18: Repeat Spine Referrer | F18: 89 | G18: 3 | H18: 0 | I18: 3 | J18: 2026-03-20 | K18: 2026-06-15 | L18: 31 | M18: 66 | N18: 14 | O18: K-D06 | P18: Madison Heights | Q18: 26393 Dequindre Rd, Madison Heights, Michigan, 48071 | R18: Erica Balysh, DO (1 spine) · Colin David Orrin, DO (1 spine) · Erica N Balysh, DO (1 spine)
A19: GARDEN CITY FAMILY PHYSICIANS | B19: be4c4280-49d5-443c-b413-3471ee753d27 | C19: PCP | D19: Tier 1 | E19: Repeat Spine Referrer | F19: 89 | G19: 3 | H19: 3 | I19: 6 | J19: 2026-05-18 | K19: 2026-06-05 | L19: 41 | M19: 30.5 | N19: 14 | O19: K-D12 | P19: GARDEN CITY | Q19: 30900 FORD RD STE B, GARDEN CITY, MI, 48135 | R19: Angelica Francu, MD (3 spine)
A20: Village Medical - Livonia | B20: e3d707da-675d-4d7c-9356-2f53ec4d8a2e | C20: PCP | D20: Tier 1 | E20: Repeat Spine Referrer | F20: 85 | G20: 2 | H20: 4 | I20: 6 | J20: 2026-06-23 | K20: 2026-06-30 | L20: 16 | M20: 40.5 | N20: 14 | O20: K-D08 | P20: Livonia | Q20: 17800 Newburgh Road, Livonia, Michigan, 48152 | R20: Martin Erickson, DO (1 spine) · Village Medical Livonia (1 spine) · Sherri Rosenfeld, DO (2 ortho) · Paul Jackson, DO (1 ortho) · Joann Van Oast, PA (1 ortho)
A21: Pulmonary & Medical Associates | B21: dda630a5-9d61-49cd-bec6-61084e47ddb9 | C21: PCP | D21: Tier 1 | E21: Repeat Spine Referrer | F21: 85 | G21: 2 | H21: 5 | I21: 8 | J21: 2026-07-09 | K21: 2026-07-13 | L21: 3 | M21: 47.5 | N21: 14 | O21: K-D13 | P21: Warren | Q21: 27472 Schoenherr Rd #100, Warren, MI, 48088 | R21: Shanna Pearson, DO (2 spine)
A22: Powers Family Medicine | B22: 00-761-7874 | C22: PCP | D22: Tier 1 | E22: Repeat Spine Referrer | F22: 84 | G22: 2 | H22: 1 | I22: 3 | J22: 2026-04-20 | K22: 2026-05-13 | L22: 64 | M22: 57 | N22: 14 | O22: K-D01 | P22: Farmington Hills | Q22: 23700 Orchard Lake Rd, Farmington Hills, MI, 48336-2559 | R22: Sommer Shefferly, PA-C (2 spine) · William John Powers, DO (1 ortho)
A23: Medical Clinic of Northville | B23: ebcb6f7a-eb6b-4759-81d9-516e3dc36b67 | C23: PCP | D23: Tier 1 | E23: Repeat Spine Referrer | F23: 84 | G23: 2 | H23: 16 | I23: 18 | J23: 2026-06-26 | K23: 2026-06-04 | L23: 42 | M23: 22 | N23: 14 | O23: K-D14 | P23: Northville | Q23: 308 S Main St, Northville, Michigan, 48167 | R23: Ross A Summers, MD (1 spine) · Cheryl Anne Johnstone, MD (1 spine) · Mirella F Ducu, MD (5 ortho) · Mirella Ducu, MD (3 ortho) · Ross Summers, MD (2 ortho) · Lauren Cislo, PA (1 ortho)
A24: Village Medical Farmington | B24: 8a6ae159-0242-4272-b933-bd11fc117733 | C24: PCP | D24: Tier 1 | E24: Repeat Spine Referrer | F24: 83 | G24: 2 | H24: 1 | I24: 4 | J24: 2026-05-21 | K24: 2026-05-11 | L24: 66 | M24: 26 | N24: 14 | O24: K-D01 | P24: Farmington | Q24: 23133 Orchard Lake Rd, Farmington, Michigan, 48336 | R24: Sandra Sabb, MD (1 spine) · Sheldon L Stern, DO (1 spine) · Sheldon Stern, DO
A25: MedPro Primary Care | B25: eebb725b-b031-43b9-a3d7-bfa83d77bc18 | C25: Urgent Care | D25: Tier 1 | E25: Repeat Spine Referrer | F25: 83 | G25: 2 | H25: 2 | I25: 4 | J25: 2026-04-10 | K25: 2026-06-15 | L25: 31 | M25: 30.5 | N25: 14 | O25: K-D04 | P25: Madison Heights | Q25: 31005 John R Rd suite a, Madison Heights, Michigan, 48071 | R25: Jaclyn Weber, PA (2 spine) · Samantha Demarce, NP (1 ortho)
A26: Oakland Family Practice | B26: 13ba57d5-6bc6-4d44-8d40-efd8e7131d2e | C26: PCP | D26: Tier 1 | E26: Repeat Spine Referrer | F26: 83 | G26: 2 | H26: 13 | I26: 17 | J26: 2026-07-08 | K26: 2026-06-15 | L26: 31 | M26: 23 | N26: 14 | O26: K-D04 | P26: Warren | Q26: 27650 Dequindre Road, Suite 2000, Warren, Michigan, 48092 | R26: Zachary Kranz, DO (2 spine) · Ronald Hirsch, DO (5 ortho) · Keith Hoffman Msw (3 ortho) · Rachel Hetzner D, NP (2 ortho) · Michelle Millman Fnp-c (1 ortho)
... A33: Safir Law | B33: 797c97ec-e6b4-42b3-920e-e16a6364e0c9 | C33: Attorney / Legal | D33: Tier 1 | E33: Repeat Spine Referrer | F33: 81 | G33: 2 | H33: 0 | I33: 2 | J33: 2026-03-31 | K33: 2026-02-27 | L33: 139 | M33: 24 | N33: 14 | O33: K-D02 | P33: Southfield | Q33: 29110 Inkster Road, Suite 150, Southfield, Michigan, 48034 | R33: Joel Safir (2 spine)
A34: Victor Valentino Law | B34: 740ceb33-170d-402e-b5c2-8c204cf2bdf4 | C34: Attorney / Legal | D34: Tier 1 | E34: Repeat Spine Referrer | F34: 81 | G34: 2 | H34: 1 | I34: 3 | J34: 2026-04-02 | K34: 2026-05-15 | L34: 62 | M34: 12 | N34: 14 | O34: K-D09 | Q34: 43494 Woodward Ave Bloomfield Township, Michigan, 48302 | R34: Victor Valentino (2 spine)
A35: Steinberg Law Firm | B35: 8f912f3f-f54b-4694-984f-06c26dcbe2a8 | C35: Attorney / Legal | D35: Tier 1 | E35: Repeat Spine Referrer | F35: 80 | G35: 2 | H35: 0 | I35: 2 | J35: 2026-02-13 | K35: 2026-04-02 | L35: 105 | M35: 13 | N35: 14 | O35: K-D10 | P35: Southfield | Q35: 29777 Telegraph Rd suite 1555, Southfield, Michigan, 48034 | R35: Eric Steinberg (2 spine)
A36: AGHA INTERNAL MEDICINE AND ASSOCIATES, PC | B36: 85fd21cb-8cbc-4ead-9b3d-0cdbecdf7638 | C36: PCP | D36: Tier 1 | E36: One Spine Patient | F36: 72 | G36: 1 | H36: 2 | I36: 3 | J36: 2026-06-08 | K36: 2026-06-29 | L36: 17 | M36: 49 | N36: 14 | O36: K-D08 | P36: LIVONIA | Q36: 15604 FARMINGTON RD, LIVONIA, MI, 48154 | R36: Hooman Agha, MD (1 spine)
A37: Henry Ford Health Medical Center - Seven Mile Road | B37: 44019f00-063b-4cdc-83d9-96ee51f8c6e3 | C37: PCP | D37: Tier 1 | E37: One Spine Patient | F37: 72 | G37: 1 | H37: 1 | I37: 3 | J37: 2026-06-17 | K37: 2026-06-30 | L37: 16 | M37: 26 | N37: 14 | O37: K-D08 | P37: LIVONIA | Q37: 37508 W SEVEN MILE RD, LIVONIA, Michigan | R37: Matthew W Benedix, DO (1 spine) · Courtney Mehock, DO (1 ortho)
A38: ROSE MEDICINE | B38: 9c2f2817-fae0-4fb0-b943-376aef6fc719 | C38: PCP | D38: Tier 1 | E38: One Spine Patient | F38: 72 | G38: 1 | H38: 0 | I38: 1 | J38: 2026-01-09 | K38: 2026-07-08 | L38: 8 | M38: 56 | N38: 14 | O38: K-D10 | P38: BINGHAM FARMS | Q38: 31500 TELEGRAPH RD STE 115, BINGHAM FARMS, MI, 48025 | R38: Oluwasayo Akinyosoye, MD (1 spine)
A39: Henry Ford Warren Family Physicians | B39: 6771a475-3022-40fd-9db9-b8e0291f7082 | C39: PCP | D39: Tier 1 | E39: One Spine Patient | F39: 72 | G39: 1 | H39: 2 | I39: 4 | J39: 2026-05-08 | K39: 2026-07-15 | L39: 1 | M39: 44 | N39: 14 | O39: K-D13 | P39: Warren | Q39: 11270 East Thirteen Mile Road, Warren, Michigan, 48093 | R39: Randall Colvin, MD (1 spine) · Kristen Panozzo, DO (2 ortho) · Nabil Rizk, MD
A40: Corewell Health-East | B40: 04ad9387-b1fe-45cd-bd14-73188de8e04a | C40: PCP | D40: Tier 1 | E40: One Spine Patient | F40: 72 | G40: 1 | H40: 0 | I40: 1 | J40: 2026-02-25 | K40: 2026-07-13 | L40: 3 | M40: 23 | N40: 14 | O40: K-D13 | P40: Warren | Q40: 29245 Ryan Rd suite 300, Warren, Michigan, 48092 | R40: Pu Qin, MD (1 spine)
A41: Huron Family Practice Center | B41: 60ee8106-1f15-4abf-95a1-c2184761b159 | C41: PCP | D41: Tier 1 | E41: One Spine Patient | F41: 72 | G41: 1 | H41: 0 | I41: 1 | J41: 2026-05-22 | K41: 2026-06-25 | L41: 21 | M41: 31 | N41: 14 | O41: K-D16 | P41: Port Huron | Q41: 1225 10th St, Port Huron, Michigan, 48060 | R41: Autumn A Whitten, PA-C (1 spine)
A42: Brentwood Pediatric Associates | B42: 9dfbaa38-07b2-4017-9d71-ff4cd2ce42f7 | C42: Pediatrics | D42: Tier 1 | E42: One Spine Patient | F42: 71 | G42: 1 | H42: 9 | I42: 11 | J42: 2026-07-09 | K42: 2026-06-30 | L42: 16 | M42: 46 | N42: 14 | O42: K-D08 | P42: Livonia | Q42: 33215 W Seven Mile Rd, Livonia, Michigan, 48152 | R42: Ajey V Godbole, MD (1 spine) · Hassan Bazzy, DO (1 ortho) | S42: Pediatric (Jul 20 rule) → KEEP - producing; verify relationship
A43: Northpointe Pediatrics | B43: 31b0544c-cc2c-4479-9df9-b11748ecefc7 | C43: Pediatrics | D43: Tier 1 | E43: One Spine Patient | F43: 71 | G43: 1 | H43: 3 | I43: 4 | J43: 2026-03-04 | K43: 2026-07-15 | L43: 1 | M43: 46.5 | N43: 14 | O43: K-D13 | P43: Warren | Q43: 30061 Schoenherr Rd, Warren, Michigan, 48088 | R43: Deanna Denysenko, DO (1 spine) · Allison Engel, MD (1 ortho) · Peter J Francis, MD (1 ortho) | S43: Pediatric (Jul 20 rule) → KEEP - producing; verify relationship
A44: FERRIS, MARY C, MEDICAL GROUP | B44: a5a045ce-889d-4018-81f5-3fd8d3d7af6b | C44: PCP | D44: Tier 1 | E44: One Spine Patient | F44: 71 | G44: 1 | H44: 6 | I44: 7 | J44: 2026-07-09 | K44: 2026-07-13 | L44: 3 | M44: 52 | N44: 14 | O44: K-D13 | P44: WARREN | Q44: 28111 HOOVER RD STE 1A, WARREN, Michigan | R44: Mary C Ferris, DO (1 spine)
A45: Swetech Medical Center | B45: 1255427209 | C45: PCP | D45: Tier 1 | E45: One Spine Patient | F45: 71 | G45: 1 | H45: 0 | I45: 2 | J45: 2026-05-14 | K45: 2026-06-15 | L45: 31 | M45: 42 | N45: 14 | O45: K-D15 | P45: Clinton Township | Q45: 43600 Garfield Rd, Clinton Township, Michigan, 48038 | R45: Jonathan Swetech, DO (1 spine) · Maria Swetech, MD
A46: Michigan Neurology and Spine Center | B46: 137ab9e0-c65d-4932-9dc5-f8b83b872e50 | C46: Pain | D46: Tier 1 | E46: One Spine Patient | F46: 71 | G46: 1 | H46: 0 | I46: 1 | J46: 2026-05-12 | K46: 2026-06-16 | L46: 30 | M46: 21 | N46: 14 | O46: K-D16 | P46: Port Huron | Q46: 1103 7th St suite a, Port Huron, Michigan, 48060 | R46: Carol Miller Fnp-bc (1 spine)
...

Sheet Jasmine
A1: Account / Practice | B1: MMC Company ID | C1: Practice Type | D1: Tier | E1: Referral Evidence Band | F1: Target Score | G1: Spine 2026 | H1: Ortho 2026 | I1: Total B2B 2026 | J1: Last Spine Patient | K1: Last Completed Visit | L1: Days Since Visit | M1: Median Visit→Appt Lag | N1: Planned Cadence (d) | O1: Route Day | P1: City | Q1: Full Address | R1: Known Referring Providers | S1: Pre-Flag (auto) | T1: Disposition | U1: Final Practice Type | V1: Final Tier | W1: Spine Opportunity | X1: Employed Spine/Neuro Provider? | Y1: Competitor / Referral Restriction? | Z1: Recommended Cadence (d) | AA1: Removal / Reassignment Reason | AB1: PL Notes
A2: [EXAMPLE] Sample Family Medicine | B2: — | C2: PCP | D2: Tier 2 | E2: Ortho Referrer | F2: 48 | G2: 0 | H2: 3 | I2: 4 | K2: 2026-06-12 | L2: 39 | N2: 21 | O2: K-D03 | P2: Livonia | Q2: 123 Example Rd | R2: Dr. A. Sample (3 ortho) | T2: Keep | U2: PCP | V2: Tier 2 | W2: Medium | X2: No | Y2: No | Z2: 21 | AB2: Solid ortho sender; pitch spine pathway next visit
A3: DMC SPORTS MEDICINE NOVI | B3: 6e52135e-6cca-4482-9973-58d180f1dce7 | C3: Orthopedic | D3: Tier 1 | E3: Repeat Spine Referrer | F3: 100 | G3: 7 | H3: 0 | I3: 7 | J3: 2026-06-19 | K3: 2026-06-24 | L3: 22 | M3: 32 | N3: 14 | O3: J-D08 | P3: NOVI | Q3: 44000 W 12 MILE RD STE 100, NOVI, MI, 48377 | R3: Robert Meehan, MD (2 spine)
A4: Comprehensive Healthcare Associates and Prevention Medicine | B4: c7781046-a235-49fa-ac8e-4b8d6354c618 | C4: PCP | D4: Tier 1 | E4: Repeat Spine Referrer | F4: 99 | G4: 6 | H4: 16 | I4: 24 | J4: 2026-06-30 | K4: 2026-07-09 | L4: 7 | M4: 23 | N4: 14 | O4: J-D01 | P4: Livonia | Q4: 15140 Levan Rd, Livonia, Michigan, 48154 | R4: Babu Jarodiya, MD (5 spine) · Jaya Vankayalapati, MD (1 spine) · Rakesh Patel, MD (3 ortho) · Jaspal Singh, MD (2 ortho)
A5: Park Medical Centers - Canton | B5: 047f1f57-d796-4b0d-b2d0-b5d576ad50ea | C5: PCP | D5: Tier 1 | E5: Repeat Spine Referrer | F5: 98 | G5: 5 | H5: 3 | I5: 9 | J5: 2026-07-07 | K5: 2026-07-02 | L5: 14 | M5: 28 | N5: 14 | O5: J-D03 | P5: CANTON | Q5: 8532 N CANTON CENTER RD, CANTON, MI, 48187 | R5: William F Rollins, DO (4 spine) · William Rollins, DO (1 spine)
A6: Synergy Medical Primary Care | B6: 5cb01f9c-faec-4c04-b600-f0eba085f6a3 | C6: PCP | D6: Tier 1 | E6: Repeat Spine Referrer | F6: 91 | G6: 4 | H6: 14 | I6: 19 | J6: 2026-06-25 | K6: 2026-07-08 | L6: 8 | M6: 18 | N6: 14 | O6: J-D04 | P6: Livonia | Q6: 9216 Middlebelt Rd, Livonia, Michigan, 48150 | R6: Hetal Gandhi, MD (3 spine) · Katie Simkow, NP (1 spine) · Miranda Sattam, PA-C (1 ortho)
A7: CANTON FAMILY HEALTH LLC | B7: 3acfe2ff-d550-4785-99aa-a1ea91ef7da4 | C7: PCP | D7: Tier 1 | E7: Repeat Spine Referrer | F7: 90 | G7: 4 | H7: 1 | I7: 6 | J7: 2026-07-06 | K7: 2026-07-06 | L7: 10 | M7: 44.5 | N7: 14 | O7: J-D01 | P7: CANTON | Q7: 6300 N HAGGERTY RD STE 220, CANTON, MI, 48187 | R7: Samih Mike Ajami, DO (4 spine) · Shadia Yeihey, MD (1 ortho)
A8: QuickDoc Urgent Care | B8: 20e3535a-e9f3-4760-9cd8-6e86789495da | C8: Urgent Care | D8: Tier 1 | E8: Repeat Spine Referrer | F8: 89 | G8: 4 | H8: 0 | I8: 4 | J8: 2026-05-28 | K8: 2026-05-12 | L8: 65 | M8: 11 | N8: 14 | O8: J-D05 | P8: Eastpointe | Q8: 19070 East 10 Mile Road, Eastpointe, Michigan, 48021 | R8: Mohamad Rahbar, MD (4 spine)
A9: NORLIVO INTERNAL MEDICINE | B9: 74262c96-dd4b-4b92-acd7-c43ebba4c04f | C9: Orthopedic | D9: Tier 1 | E9: Repeat Spine Referrer | F9: 91 | G9: 3 | H9: 7 | I9: 10 | J9: 2026-06-05 | K9: 2026-06-09 | L9: 37 | M9: 19 | N9: 14 | O9: J-D09 | P9: Livonia | Q9: 20311 Farmington Road, Livonia, Michigan, 48152 | R9: Amadeo R Sturla, MD (2 spine) · Amadeo Sturla, MD (1 spine)
A10: OAK STREET HEALTH CHERRY HILL | B10: 0cc06713-910b-4b74-ba14-7cd3d76b3c62 | C10: PCP | D10: Tier 1 | E10: Repeat Spine Referrer | F10: 88 | G10: 3 | H10: 14 | I10: 21 | J10: 2026-06-25 | K10: 2026-04-22 | L10: 85 | M10: 22 | N10: 14 | O10: J-D02 | P10: INKSTER | Q10: 27155 CHERRY HILL RD, INKSTER, MI, 48141 | R10: Peter Vasquez, MD (1 spine) · Nadine Larcher, NP (1 spine) · Oakstreet Health - Cherry Hill (1 spine) · Gaybriel Morrell, MD (4 ortho)
A11: Premier Medicine Medical Center - Livonia | B11: 13842362-6701-47f3-95cc-140ea17bd264 | C11: Urgent Care | D11: Tier 1 | E11: Repeat Spine Referrer | F11: 85 | G11: 2 | H11: 5 | I11: 7 | J11: 2026-06-19 | K11: 2026-06-26 | L11: 20 | M11: 30 | N11: 14 | O11: J-D10 | P11: Livonia | Q11: 20290 Middlebelt Rd, Livonia, Michigan, 48152 | R11: Nabil Suliman, MD (1 spine) · Monica Fukala, NP (1 spine) · Somnath Chowdhury, MD (1 ortho)
A12: Frank Lanzilote DO-Family Practice | B12: 1d143d90-6122-41e7-ae14-c14d4e4317b4 | C12: PCP | D12: Tier 1 | E12: Repeat Spine Referrer | F12: 84 | G12: 2 | H12: 18 | I12: 23 | J12: 2026-06-12 | K12: 2026-05-21 | L12: 56 | M12: 15 | N12: 14 | O12: J-D11 | P12: Detroit | Q12: 16226 Grand River Ave, Detroit, Michigan, 48227 | R12: Pooja Kodali, MD (2 spine)
A13: Grand River Medical Associates | B13: 218209bd-0e83-4585-b5e7-1455814e77b1 | C13: PCP | D13: Tier 1 | E13: Repeat Spine Referrer | F13: 82 | G13: 2 | H13: 0 | I13: 2 | J13: 2026-06-30 | K13: 2026-04-14 | L13: 93 | M13: 73.5 | N13: 14 | O13: J-D12 | P13: New Hudson | Q13: 55840 Grand River Ave ste 300, New Hudson, Michigan, 48165 | R13: Jamie G Taweel, DO (2 spine)
A14: Livonia Family Medical Center | B14: 68ceff67-99ac-4ef7-a162-918f93bbdf38 | C14: PCP | D14: Tier 1 | E14: One Spine Patient | F14: 72 | G14: 1 | H14: 1 | I14: 3 | J14: 2026-05-05 | K14: 2026-06-26 | L14: 20 | M14: 27 | N14: 14 | O14: J-D04 | P14: Livonia | Q14: 28701 Plymouth Rd, Livonia, Michigan, 48150 | R14: Keith M Tobin, DO (1 spine) · Michael Burry, DO (1 ortho)
... A57: CENTER FOR INTERNAL MEDICINE CONTINUITY CLINIC | B57: ce969d89-5e72-4361-9024-039ad31f5bc3 | C57: PCP | D57: Tier 2 | E57: Ortho Referrer | F57: 47 | G57: 0 | H57: 1 | I57: 1 | J57: 2026-01-13 | K57: 2026-06-12 | L57: 34 | M57: 29 | N57: 21 | O57: J-D16 | P57: LIVONIA | Q57: 28479 7 MILE RD, LIVONIA, MI, 48152 | R57: Hao Nguyen, DO (1 ortho)
A58: UofM Canton Health Center General Medicine | B58: 400aeb1f-6186-4eb7-98c8-0544491af836 | C58: PCP | D58: Tier 2 | E58: Ortho Referrer | F58: 47 | G58: 0 | H58: 1 | I58: 1 | J58: 2026-06-03 | K58: 2026-06-11 | L58: 35 | M58: 34 | N58: 21 | O58: J-D18 | P58: Canton | Q58: 1051 North Canton Center Road, Canton, Michigan, 48187 | R58: Kristin M Collier, MD (1 ortho) | S58: Medicaid-likely — verify payer
A59: MI Express Urgent Care | B59: fc1455cf-74a6-4b97-b05f-e677351745de | C59: Orthopedic | D59: Tier 2 | E59: Ortho Referrer | F59: 47 | G59: 0 | H59: 1 | I59: 1 | J59: 2026-07-06 | K59: 2026-06-11 | L59: 35 | M59: 25 | N59: 21 | O59: J-D27 | P59: Ann Arbor | Q59: 80 South Zeeb Road, Ann Arbor, Michigan, 48103 | R59: MI Express Urgent Care (1 ortho)
A60: Michigan Primary Care - Eastpointe | B60: 4328f444-1a86-4fbb-9849-e8a159cce3e2 | C60: PCP | D60: Tier 2 | E60: Ortho Referrer | F60: 46 | G60: 0 | H60: 1 | I60: 1 | J60: 2026-06-04 | K60: 2026-05-12 | L60: 65 | M60: 23 | N60: 21 | O60: J-D05 | P60: Eastpointe | Q60: 17000 E 10 Mile Rd, Eastpointe, MI, 48021 | R60: Colleen Miller, NP (1 ortho)
A61: Office of Jeff The DO | B61: 1710940242 | C61: PCP | D61: Tier 2 | E61: Ortho Referrer | F61: 46 | G61: 0 | H61: 1 | I61: 1 | J61: 2026-03-19 | K61: 2026-07-13 | L61: 3 | M61: 28 | N61: 21 | O61: J-D23 | P61: Plymouth | Q61: 990 West Ann Arbor Trail, Plymouth, Michigan, 48170 | R61: Jeff Y The, DO (1 ortho)
A62: BADHWAR ASSOCIATES, MD, PC | B62: 930e15d8-29b2-49a1-be3d-7eae0da7dc41 | C62: PCP | D62: Tier 2 | E62: Ortho Referrer | F62: 46 | G62: 0 | H62: 1 | I62: 1 | J62: 2026-05-13 | K62: 2026-05-29 | L62: 48 | M62: 107 | N62: 21 | O62: J-D28 | P62: BROWNSTOWN | Q62: 19135 ALLEN RD STE 106, BROWNSTOWN, MI, 48183 | R62: Avlokita Badhwar, MD (1 ortho)
A63: Wayne Primary Care and Walk In | B63: 607852d7-cb70-46f8-ac4a-ed6f36b0acf9 | C63: Urgent Care | D63: Tier 2 | E63: Ortho Referrer | F63: 45 | G63: 0 | H63: 1 | I63: 1 | J63: 2026-01-15 | K63: 2026-06-08 | L63: 38 | M63: 10 | N63: 21 | O63: J-D02 | P63: Wayne | Q63: 4020 Venoy Rd suite 400, Wayne, Michigan, 48184 | R63: Vijay Patel, MD (1 ortho)
A64: MEDICAL GROUP PRACTICE, PC (Olympia health) | B64: 931a0b27-6417-43b6-a15a-c3eac7f8203a | C64: PCP | D64: Tier 2 | E64: Ortho Referrer | F64: 45 | G64: 0 | H64: 1 | I64: 1 | J64: 2026-04-13 | K64: 2026-03-03 | L64: 135 | M64: 41 | N64: 21 | O64: J-D04 | P64: LIVONIA | Q64: 9460 MIDDLEBELT RD, LIVONIA, MI, 48150 | R64: William Paul Penn, DO (1 ortho)
A65: The family Doc | B65: 3b5d6ffd-3a5a-4ccd-b656-e2340f7c8ea5 | C65: PCP | D65: Tier 2 | E65: Ortho Referrer | F65: 45 | G65: 0 | H65: 1 | I65: 1 | J65: 2026-03-16 | K65: 2026-02-26 | L65: 140 | M65: 18 | N65: 21 | O65: J-D11 | P65: Dearborn Heights | Q65: 25350 West Warren Street, Dearborn Heights, Michigan, 48127 | R65: Ali I Nasrallah, MD (1 ortho)
A66: Care Medical Clinic of Canton | B66: 1356380513 | C66: PCP | D66: Tier 2 | E66: Ortho Referrer | F66: 45 | G66: 0 | H66: 1 | I66: 1 | J66: 2026-05-08 | K66: 2026-06-02 | L66: 44 | M66: 53 | N66: 21 | O66: J-D18 | P66: Canton | Q66: 5730 N Lilley Rd, ste C, Canton, MI, 48187 | R66: Paul G Debrincat (1 ortho)
A67: Corwell internal medicine and primary care | B67: 3a2a1db5-c1c4-41cd-a7f3-b4e0b388e268 | C67: PCP | D67: Tier 2 | E67: Ortho Referrer | F67: 45 | G67: 0 | H67: 1 | I67: 1 | J67: 2026-06-08 | K67: 2026-06-09 | L67: 37 | N67: 21 | O67: J-D25 | P67: Livonia | Q67: 37633 Pembroke Avenue, Livonia, Michigan, 48152 | R67: Elaina Vayntrub, MD (1 ortho)
A68: City Medical - Southgate | B68: 1326021262 | C68: PCP | D68: Tier 2 | E68: Ortho Referrer | F68: 45 | G68: 0 | H68: 1 | I68: 1 | J68: 2026-05-08 | K68: 2026-04-22 | L68: 85 | M68: 16 | N68: 21 | O68: J-D28 | P68: Southgate | Q68: 13636 Dix Toledo, Southgate, MI, 481952432 | R68: Nabeel Omar, PA-C (1 ortho)
A69: Schaefer Medical | B69: a5a464ab-73df-48e0-8f49-b80f6b89fc6b | C69: PCP | D69: Tier 2 | E69: Ortho Referrer | F69: 45 | G69: 0 | H69: 1 | I69: 1 | J69: 2026-04-17 | K69: 2026-05-06 | L69: 71 | M69: 85 | N69: 21 | O69: J-D29 | P69: Dearborn | Q69: 5245 Schaefer Rd, Dearborn, Michigan, 48126 | R69: Nesrene Ghani, MD (1 ortho)
A70: TERRY D HOWELL, MD, PC | B70: 4e57efb6-1ae9-4171-ac14-4be29705805c | C70: PCP | D70: Tier 2 | E70: Ortho Referrer | F70: 45 | G70: 0 | H70: 1 | I70: 1 | J70: 2026-06-22 | K70: 2025-10-20 | L70: 269 | M70: 245 | N70: 21 | O70: J-D30 | P70: SALINE | Q70: 401 N ANN ARBOR ST STE D, SALINE, MI, 48176 | R70: Terry Howell, MD (1 ortho)
A71: PEDIATRIC AND ADOLESCENT CENTER | B71: 31fe13d8-1060-4c98-bf75-61f09e803121 | C71: Pediatrics | D71: Tier 2 | E71: Ortho Referrer | F71: 44 | G71: 0 | H71: 1 | I71: 1 | J71: 2026-02-09 | K71: 2026-04-22 | L71: 85 | M71: 98 | N71: 21 | O71: J-D28 | P71: Southgate | Q71: 15555 Northline Road, Southgate, Michigan, 48195 | R71: Dinesh Nayak, MD (1 ortho) | S71: Pediatric (Jul 20 rule) → Review for removal
A72: CANTON FOOT & Ankle SPECIALISTS | B72: 13dc6a74-7486-4022-8993-7eaf6b95734e | C72: Podiatry | D72: Tier 2 | E72: Ortho Referrer | F72: 43 | G72: 0 | H72: 1 | I72: 1 | J72: 2026-01-20 | K72: 2026-01-15 | L72: 182 | M72: 5 | N72: 21 | O72: J-D03 | P72: Canton | Q72: 43050 Ford Road Ste 150, Canton, Michigan, 48187 | R72: Brandon Semma (1 ortho)
A73: Novi Medicine | B73: bd0ee186-9de1-49f1-b6f7-85fc538efd3b | C73: PCP | D73: Tier 3 | E73: Other Patient Referrer | F73: 35 | G73: 0 | H73: 0 | I73: 4 | J73: 2026-05-26 | K73: 2026-07-15 | L73: 1 | M73: 8 | N73: 30 | O73: J-D08 | P73: NOVI | Q73: 39475 LEWIS DR STE 150, NOVI, MI, 48377 | R73: Lowell Paul, MD
A74: DEDICATED SENIOR MEDICAL CENTER - Southfield | B74: 12deaf83-0f5e-4bd5-bf07-a4026935ffd1 | C74: Orthopedic | D74: Tier 3 | E74: Other Patient Referrer | F74: 29 | G74: 0 | H74: 0 | I74: 2 | J74: 2026-06-22 | K74: 2026-06-25 | L74: 21 | M74: 8 | N74: 30 | O74: J-D14 | P74: Southfield | Q74: 21816 w 11 mile rd, Southfield, Michigan, 48076 | R74: Sally Azzo, MD · Vishnuvardhan G Reddy, MD
A75: Corewell Health Farmington hills Hospital family medicine | B75: a2a230c5-b58c-4416-a519-b3d118d15202 | C75: PCP | D75: Tier 3 | E75: Other Patient Referrer | F75: 28 | G75: 0 | H75: 0 | I75: 2 | J75: 2026-06-18 | K75: 2026-07-08 | L75: 8 | M75: 29.5 | N75: 30 | O75: J-D25 | P75: LIVONIA | Q75: 39000 7 MILE RD Suite 4300, LIVONIA, MI, 48152 | R75: Kerry L Stone, PA · Matteo Valenti, DO
A76: ASCENSION MEDICAL GROUP WEST BLOOMFIELD FAMILY PRACTICE | B76: 611f52cc-838d-405e-8988-68708f39608e | C76: PCP | D76: Tier 3 | E76: Other Patient Referrer | F76: 24 | G76: 0 | H76: 0 | I76: 1 | J76: 2026-03-03 | K76: 2026-07-15 | L76: 1 | M76: 8 | N76: 30 | O76: J-D08 | P76: NOVI | Q76: 28455 HAGGERTY RD STE 100, NOVI, MI, 48377 | R76: Bethany Clary, MD
A77: PONDURI, KAVITHA, MEDICAL GROUP | B77: b873599c-56bb-4876-b2ec-95215a325efb | C77: PCP | D77: Tier 3 | E77: Other Patient Referrer | F77: 24 | G77: 0 | H77: 0 | I77: 1 | J77: 2026-03-23 | K77: 2026-07-13 | L77: 3 | M77: 14 | N77: 30 | O77: J-D15 | P77: Wayne | Q77: 34659 West Michigan Avenue, Wayne, Michigan, 48184 | R77: Kavitha Ponduri, MD
A78: Park Family Practice - Novi | B78: 210797fc-d818-410f-94de-02c502935d29 | C78: PCP | D78: Tier 3 | E78: Other Patient Referrer | F78: 24 | G78: 0 | H78: 0 | I78: 1 | J78: 2026-07-09 | K78: 2026-06-23 | L78: 23 | M78: 16 | N78: 30 | O78: J-D20 | P78: NOVI | Q78: 26850 PROVIDENCE PKWY STE 370, NOVI, MI, 48374 | R78: Megan Schram, PA
A79: Corewell Urgent Care - Novi | B79: e996949d-e85c-4588-a081-deb7cdc8510a | C79: Urgent Care | D79: Tier 3 | E79: Other Patient Referrer | F79: 24 | G79: 0 | H79: 0 | I79: 1 | J79: 2026-04-22 | K79: 2026-06-23 | L79: 23 | M79: 21 | N79: 30 | O79: J-D20 | P79: Novi | Q79: 43535 Grand River, Novi, Michigan, 48375 | R79: Corewell Urgent Care - Novi
A80: BEAUMONT FAMILY MEDICINE GARDEN CITY | B80: 796ef668-29ca-4cac-84b8-fd8125eb6bde | C80: PCP | D80: Tier 3 | E80: Other Patient Referrer | F80: 23 | G80: 0 | H80: 0 | I80: 1 | J80: 2026-03-30 | K80: 2026-06-15 | L80: 31 | M80: 27 | N80: 30 | O80: J-D02 | P80: GARDEN CITY | Q80: 29150 FORD RD, GARDEN CITY, MI, 48135 | R80: Mariam Abdulghani, MD
A81: SOUTHFIELD URGENT CARE | B81: f8db03fe-3188-4a31-b4ee-6010086c7552 | C81: Urgent Care | D81: Tier 3 | E81: Other Patient Referrer | F81: 22 | G81: 0 | H81: 0 | I81: 1 | J81: 2026-06-08 | K81: 2026-06-29 | L81: 17 | M81: 87 | N81: 30 | O81: J-D14 | P81: SOUTHFIELD | Q81: 23832 SOUTHFIELD RD STE 1, SOUTHFIELD, Michigan | R81: Southfield Urgent Care
A82: Integrative Family Medicine Clinic - Domino's Farms (U of M) | B82: 2ca32d51-676d-49f5-8e79-835774431e9d | C82: PCP | D82: Tier 3 | E82: Other Patient Referrer | F82: 21 | G82: 0 | H82: 0 | I82: 1 | J82: 2026-03-31 | K82: 2026-04-15 | L82: 92 | M82: 40 | N82: 30 | O82: J-D27 | P82: Ann Arbor | Q82: 24 Frank Lloyd Wright Dr ste 2300 lobby h, Ann Arbor, Michigan, 48105 | R82: Gregory Shumer, MD
...

Sheet Coty
A1: Account / Practice | B1: MMC Company ID | C1: Practice Type | D1: Tier | E1: Referral Evidence Band | F1: Target Score | G1: Spine 2026 | H1: Ortho 2026 | I1: Total B2B 2026 | J1: Last Spine Patient | K1: Last Completed Visit | L1: Days Since Visit | M1: Median Visit→Appt Lag | N1: Planned Cadence (d) | O1: Route Day | P1: City | Q1: Full Address | R1: Known Referring Providers | S1: Pre-Flag (auto) | T1: Disposition | U1: Final Practice Type | V1: Final Tier | W1: Spine Opportunity | X1: Employed Spine/Neuro Provider? | Y1: Competitor / Referral Restriction? | Z1: Recommended Cadence (d) | AA1: Removal / Reassignment Reason | AB1: PL Notes
A2: [EXAMPLE] Sample Family Medicine | B2: — | C2: PCP | D2: Tier 2 | E2: Ortho Referrer | F2: 48 | G2: 0 | H2: 3 | I2: 4 | K2: 2026-06-12 | L2: 39 | N2: 21 | O2: K-D03 | P2: Livonia | Q2: 123 Example Rd | R2: Dr. A. Sample (3 ortho) | T2: Keep | U2: PCP | V2: Tier 2 | W2: Medium | X2: No | Y2: No | Z2: 21 | AB2: Solid ortho sender; pitch spine pathway next visit
A3: Lakeview Medical Center | B3: 64ed5116-24c0-4278-8d87-a7ca5f7d76c4 | C3: PCP | D3: Tier 1 | E3: Repeat Spine Referrer | F3: 99 | G3: 7 | H3: 6 | I3: 13 | J3: 2026-05-14 | K3: 2026-07-09 | L3: 7 | M3: 15 | N3: 14 | O3: C-D06 | P3: St. Clair Shores | Q3: 23600 Harper Ave ste 103 St Clair Shores, St. Clair Shores, Michigan, 48080 | R3: Magdy Wanis, MD (5 spine) · Rachel N Kloski, PA-C (2 spine)
A4: Schoenherr Family Practice | B4: e9020844-6b2a-43b6-9416-51116e859cc2 | C4: PCP | D4: Tier 1 | E4: Repeat Spine Referrer | F4: 99 | G4: 6 | H4: 2 | I4: 8 | J4: 2026-06-04 | K4: 2026-07-07 | L4: 9 | M4: 17 | N4: 14 | O4: C-D07 | P4: Shelby Township | Q4: 13350 24 Mile Rd ste 200, Shelby Township, Michigan, 48315 | R4: Kelly K Machesky, MD (6 spine) · Matthew Romano (1 ortho)
A5: Office of George Nassif MD | B5: 1225209075 | C5: PCP | D5: Tier 1 | E5: Repeat Spine Referrer | F5: 91 | G5: 4 | H5: 0 | I5: 4 | J5: 2026-06-15 | K5: 2026-06-18 | L5: 28 | M5: 29.5 | N5: 14 | O5: C-D08 | P5: Clinton Township | Q5: 42621 Garfield Rd, ste 108, Clinton Township, MI, 480385031 | R5: George Helmy Nassif, MD (4 spine)
A6: North Valley Internal Medicine | B6: 063204da-544e-4bdd-a18b-f483a5c16ad9 | C6: PCP | D6: Tier 1 | E6: Repeat Spine Referrer | F6: 91 | G6: 3 | H6: 0 | I6: 3 | J6: 2026-05-22 | K6: 2026-07-16 | L6: 0 | M6: 24 | N6: 14 | O6: C-D09 | P6: Highland Charter Township | Q6: 2330 S Milford Rd, ste 120 Highland, Highland Charter Township, Michigan, 48357 | R6: Brandon Genson, DO (2 spine) · Ryan Johnston, PA-C (1 spine)
A7: Be Well Medical Center | B7: 1174554364 | C7: PCP | D7: Tier 1 | E7: Repeat Spine Referrer | F7: 88 | G7: 3 | H7: 11 | I7: 17 | J7: 2026-07-08 | K7: 2026-04-21 | L7: 86 | M7: 17 | N7: 14 | O7: C-D04 | P7: Berkley | Q7: 1964 11 Mile Rd, Berkley, MI, 48072 | R7: Mark Rosen, PA-C (1 spine) · Mark Bornstein, DO (1 spine) · Caleb Youngblood Pa C (1 spine) · Paul A Benson, DO (3 ortho) · Rosen PA-C, Mark (ZOC DOC) (1 ortho)
A8: The Family Doctor | B8: 23a703a6-5bde-4887-845c-b78a61128817 | C8: PCP | D8: Tier 1 | E8: Repeat Spine Referrer | F8: 85 | G8: 2 | H8: 1 | I8: 3 | J8: 2026-05-14 | K8: 2026-07-10 | L8: 6 | M8: 19 | N8: 14 | O8: C-D01 | P8: Clinton Township | Q8: 15501 Metro Parkway, Clinton Township, Michigan, 48036 | R8: Keith Mckenzie, MD (1 spine) · Claudia Pop, MD (1 spine)
A9: Faith Internal Medicine & Urgent Care | B9: 677326d2-4ba2-4a49-a6f1-e7633a9a8401 | C9: PCP | D9: Tier 1 | E9: Repeat Spine Referrer | F9: 85 | G9: 2 | H9: 7 | I9: 10 | J9: 2026-06-22 | K9: 2026-06-19 | L9: 27 | M9: 20 | N9: 14 | O9: C-D10 | P9: Livonia | Q9: 15645 Farmington Rd, Livonia, Michigan, 48154 | R9: Laith J Jacob Mbchb (2 spine) · Laith Jacob, MD (1 ortho)
A10: Oakland Primary Care | B10: 1952660706 | C10: PCP | D10: Tier 1 | E10: Repeat Spine Referrer | F10: 84 | G10: 2 | H10: 4 | I10: 6 | J10: 2026-06-15 | K10: 2026-06-18 | L10: 28 | M10: 24 | N10: 14 | O10: C-D11 | P10: Warren | Q10: 27450 Schoenherr, ste 400, Warren, Michigan, 48088 | R10: Jason I Soffa, DO (2 spine) · Uroob Rahman, MD (1 ortho) · Ryan Smith DO (1 ortho) · Jason Soffa, DO (1 ortho)
A11: Chronic Pain Institute | B11: 11ed7e07-a278-4fda-90ea-e3baede80121 | C11: Pain | D11: Tier 1 | E11: Repeat Spine Referrer | F11: 83 | G11: 2 | H11: 0 | I11: 2 | J11: 2026-06-30 | K11: 2026-06-02 | L11: 44 | M11: 24.5 | N11: 14 | O11: C-D01 | P11: Sterling Heights | Q11: 43145 Schoenherr Rd, Sterling Heights, Michigan, 48313 | R11: Kuldip S Deogun, MD (2 spine)
A12: MEDPRO PRIMARY CARE - Waltz Rd | B12: 5ba2b7d1-0a31-458d-95a0-4ba47f0574a0 | C12: Pain | D12: Tier 1 | E12: Repeat Spine Referrer | F12: 83 | G12: 2 | H12: 0 | I12: 2 | J12: 2026-05-18 | K12: 2026-02-17 | L12: 149 | M12: 94.5 | N12: 14 | O12: C-D12 | P12: NEW BOSTON | Q12: 21057 Waltz Rd, NEW BOSTON, Michigan, 48164 | R12: Ashleigh Finazzo, PA-C (2 spine)
A13: DMC Orthopedics & Sports Medicine - Warren | B13: 1285806067 | C13: Orthopedic | D13: Tier 1 | E13: One Spine Patient | F13: 73 | G13: 1 | H13: 0 | I13: 1 | J13: 2026-02-17 | K13: 2026-06-26 | L13: 20 | M13: 5 | N13: 14 | O13: C-D01 | P13: Sterling Heihhts | Q13: 33703 Van Dyke Ave, Sterling Heihhts, MI, 48312 | R13: Britta Anderson, DO (1 spine)
A14: Macomb Physicians Group | B14: fdefbf3e-907d-4d68-bbd3-2d70f4818b7a | C14: PCP | D14: Tier 1 | E14: One Spine Patient | F14: 72 | G14: 1 | H14: 8 | I14: 9 | J14: 2026-07-07 | K14: 2026-07-02 | L14: 14 | M14: 27 | N14: 14 | O14: C-D01 | P14: Sterling Heights | Q14: 8244 Metro Parkway, Sterling Heights, Michigan, 48312 | R14: Lalitha Koneru, MD (1 spine) · Gordhan Diora, MD (3 ortho) · Mark H Stephen, MD (2 ortho) · Mark Stephen, MD (1 ortho)
A15: Community First Health Centers - New Haven | B15: 8cef9fd7-931c-4e45-bf44-0cac47716f62 | C15: PCP | D15: Tier 1 | E15: One Spine Patient | F15: 72 | G15: 1 | H15: 0 | I15: 1 | J15: 2026-06-09 | K15: 2026-06-30 | L15: 16 | M15: 21 | N15: 14 | O15: C-D02 | P15: New Haven | Q15: 58144 Gratiot Ave, New Haven, Michigan, 48048 | R15: Shelia Singleton, MD (1 spine) | S15: Medicaid-likely — verify payer
A16: Preferred Medical Group | B16: 1356443600 | C16: Orthopedic | D16: Tier 1 | E16: One Spine Patient | F16: 72 | G16: 1 | H16: 1 | I16: 2 | J16: 2026-06-25 | K16: 2026-06-24 | L16: 22 | M16: 1 | N16: 14 | O16: C-D04 | P16: Madison Heights | Q16: 1200 W 12 Mile Rd, Madison Heights, MI, 48071 | R16: Rachel Gillespie, DPM (1 spine) · Rachael Ustruck, DO (1 ortho)
A17: Henry Ford St. John Center for Wellness | B17: 5e640eee-6b5a-442a-8222-bd81d0a228ec | C17: PCP | D17: Tier 1 | E17: One Spine Patient | F17: 72 | G17: 1 | H17: 1 | I17: 3 | J17: 2026-05-18 | K17: 2026-06-25 | L17: 21 | M17: 405 | N17: 14 | O17: C-D05 | P17: Roseville | Q17: 18303 E 10 Mile Rd #500, Roseville, Michigan, 48066 | R17: Lydia Joy Rayes, DO (1 spine)
A18: Brighton Internal Medicine | B18: 02e450b1-82e8-408a-a0a4-fa7af806ed2b | C18: PCP | D18: Tier 1 | E18: One Spine Patient | F18: 72 | G18: 1 | H18: 0 | I18: 1 | J18: 2026-01-06 | K18: 2026-07-16 | L18: 0 | M18: 63 | N18: 14 | O18: C-D13 | P18: Howell | Q18: 1225 S Latson Rd #200, Howell, Michigan, 48843 | R18: Syed Masood Shahab, MD (1 spine)
A19: Macomb Medical Clinic | B19: 1992782320 | C19: PCP | D19: Tier 1 | E19: One Spine Patient | F19: 72 | G19: 1 | H19: 10 | I19: 12 | J19: 2026-07-09 | K19: 2026-07-02 | L19: 14 | M19: 22.5 | N19: 14 | O19: C-D14 | P19: Sterling Heights | Q19: 2405 E 14 Mile Rd, Sterling Heights, MI, 48310 | R19: Jillian Monticciolo Pa C (1 spine) · Amar Kurjakovic, PA-C (4 ortho) · Mark S Rosenberg, DO (2 ortho) · David Giancola, PA (1 ortho) · Macomb Medical Clinic (1 ortho) · Brooke Tobia, PA (1 ortho)
A20: Premier Private Physicians | B20: fc79eac0-6f20-44c3-84a9-e20d7068fe4e | C20: PCP | D20: Tier 1 | E20: One Spine Patient | F20: 72 | G20: 1 | H20: 0 | I20: 1 | J20: 2026-06-09 | K20: 2026-07-13 | L20: 3 | M20: 6 | N20: 14 | O20: C-D15 | P20: Troy | Q20: 1627 W Big Beaver Rd, Troy, Michigan, 48084 | R20: Ashleigh Peoples, MD (1 spine)
A21: Bay Area Family Physicians | B21: 1093985145 | C21: PCP | D21: Tier 1 | E21: One Spine Patient | F21: 71 | G21: 1 | H21: 0 | I21: 1 | J21: 2026-06-17 | K21: 2026-05-19 | L21: 58 | M21: 29 | N21: 14 | O21: C-D02 | P21: New Baltimore | Q21: 34301 23 Mile Road, New Baltimore, MI, 48047 | R21: Eileen Hopman, MD (1 spine)
A22: North Macomb Medical Associates | B22: 7250fa4c-09c2-418b-94d4-8badec5b77f7 | C22: PCP | D22: Tier 1 | E22: One Spine Patient | F22: 71 | G22: 1 | H22: 0 | I22: 1 | J22: 2026-06-09 | K22: 2026-06-30 | L22: 16 | M22: 278 | N22: 14 | O22: C-D02 | P22: Richmond | Q22: 66440 Gratiot Ave, Richmond, Michigan, 48050 | R22: Sarah Weymouth, PA-C (1 spine)
A23: Madison Medical Arts | B23: 1760473094 | C23: PCP | D23: Tier 1 | E23: One Spine Patient | F23: 71 | G23: 1 | H23: 0 | I23: 1 | J23: 2026-06-18 | K23: 2026-06-24 | L23: 22 | M23: 57 | N23: 14 | O23: C-D03 | P23: Madison Heights | Q23: 28200 John R Road, Madison Heights, MI, 48071 | R23: Robert Hasbany, MD (1 spine)
A24: Sudha Nannapaneni MD | B24: f9518cc9-e8e8-4517-8250-4768d176ee8c | C24: PCP | D24: Tier 1 | E24: One Spine Patient | F24: 71 | G24: 1 | H24: 0 | I24: 1 | J24: 2026-01-20 | K24: 2026-06-25 | L24: 21 | M24: 76 | N24: 14 | O24: C-D05 | P24: Roseville | Q24: 18285 East 10 Mile Road, Roseville, Michigan, 48066 | R24: Sudha Nannapaneni, MD (1 spine)
A25: Office of Josephine A. Iskander MD | B25: b1e60538-ff76-457b-a530-3647907b307b | C25: PCP | D25: Tier 1 | E25: One Spine Patient | F25: 71 | G25: 1 | H25: 0 | I25: 1 | J25: 2026-06-25 | K25: 2026-07-13 | L25: 3 | M25: 57 | N25: 14 | O25: C-D16 | P25: Sterling Heights | Q25: 43200 Dequindre Rd., Ste 104 Sterling Heights, MI 48314, United States, Sterling Heights, Michigan, 48314 | R25: Josephine Iskander, MD (1 spine)
A26: Henry Ford Macomb Internal Medicine | B26: 1841213436 | C26: PCP | D26: Tier 1 | E26: One Spine Patient | F26: 70 | G26: 1 | H26: 3 | I26: 4 | J26: 2026-03-26 | K26: 2026-06-16 | L26: 30 | M26: 44.5 | N26: 14 | O26: C-D01 | P26: Sterling Heights | Q26: 13801 15 Mile Rd, Sterling Heights, Michigan, 48312 | R26: Katherine Doyle, DO (1 spine) · John C Bochenek, DO (1 ortho)
A27: Office of Steven Trombly MD | B27: 1407867815 | C27: PCP | D27: Tier 1 | E27: One Spine Patient | F27: 70 | G27: 1 | H27: 6 | I27: 7 | J27: 2026-06-29 | K27: 2026-07-09 | L27: 7 | M27: 61 | N27: 14 | O27: C-D01 | P27: Sterling Heights | Q27: 5195 15 Mile Rd, Sterling Heights, Michigan, 48310 | R27: Steven D Trombly, MD (1 spine)
... A37: Gratiot Family Medicine | B37: f7eb2b6e-6864-4576-879b-81a2bb775cb1 | C37: PCP | D37: Tier 1 | E37: One Spine Patient | F37: 68 | G37: 1 | H37: 0 | I37: 1 | J37: 2026-06-25 | K37: 2026-03-19 | L37: 119 | M37: 98 | N37: 14 | O37: C-D06 | P37: Harper Woods | Q37: 19959 Vernier Rd, Suite 200, Harper Woods, MI, 48225 | R37: Darwish Darwish (1 spine)
A38: Premiere Pediatrics | B38: a8abc02a-95b9-4318-b876-60471f8fff0e | C38: Pediatrics | D38: Tier 1 | E38: One Spine Patient | F38: 68 | G38: 1 | H38: 0 | I38: 1 | J38: 2026-06-16 | K38: 2024-11-07 | L38: 616 | M38: 586 | N38: 14 | O38: C-D22 | P38: City of the Village of Clarkston | Q38: 7210 N Main St suite 205, City of the Village of Clarkston, Michigan | R38: Mark William Thomas, MD (1 spine) | S38: Pediatric (Jul 20 rule) → KEEP - producing; verify relationship
A39: Shaun Jayakar MD | B39: f56a8949-cb8d-4abd-8405-0a939eec72d2 | C39: PCP | D39: Tier 2 | E39: Ortho Referrer | F39: 59 | G39: 0 | H39: 6 | I39: 6 | J39: 2026-07-08 | K39: 2026-07-09 | L39: 7 | M39: 20.5 | N39: 21 | O39: C-D06 | P39: St Clair Shores | Q39: 21610 9 Mile Rd, St Clair Shores, MI, 48080 | R39: Shaun M Jayakar, MD (5 ortho) · Shaun Jayakar, MD (1 ortho)
A40: Henry Ford Health Medical Center (Ascension) | B40: 3a5cf92c-ae21-4227-96ec-08c2968a5939 | C40: PCP | D40: Tier 2 | E40: Ortho Referrer | F40: 53 | G40: 0 | H40: 3 | I40: 3 | J40: 2026-06-29 | K40: 2026-06-18 | L40: 28 | M40: 11 | N40: 21 | O40: C-D05 | P40: St. Clair Shores | Q40: 24911 Little Mack Ave Ste C, St. Clair Shores, Michigan, 48080 | R40: Mary E Murphy, MD (2 ortho) · Anna Farhat, MD (1 ortho)
A41: Lakeside Internal Medicine | B41: 1c5c4e69-60f0-4d66-a3ee-9a33e818a99b | C41: PCP | D41: Tier 2 | E41: Ortho Referrer | F41: 53 | G41: 0 | H41: 3 | I41: 3 | J41: 2026-03-10 | K41: 2026-07-09 | L41: 7 | M41: 22 | N41: 21 | O41: C-D11 | P41: St Clair Shores | Q41: 21000 Twelve Mile Rd Suite 105, St Clair Shores, Michigan, 48081 | R41: Charles Skardarasy, MD (3 ortho)
A42: Progressive Health Care | B42: 1790797207 | C42: PCP | D42: Tier 2 | E42: Ortho Referrer | F42: 52 | G42: 0 | H42: 2 | I42: 2 | J42: 2026-05-14 | K42: 2026-06-17 | L42: 29 | M42: 16.5 | N42: 21 | O42: C-D04 | P42: Berkley | Q42: 2635 Coolidge Hwy, Berkley, MI, 48072 | R42: Michael Haroutunian, DO (2 ortho)
A43: ESSENTIAL CARE FAMILY MEDICINE | B43: 131adcde-9fdc-45db-af94-831482a14212 | C43: PCP | D43: Tier 2 | E43: Ortho Referrer | F43: 51 | G43: 0 | H43: 3 | I43: 3 | J43: 2026-07-08 | K43: 2026-06-25 | L43: 21 | M43: 88 | N43: 21 | O43: C-D05 | P43: SAINT CLAIR SHORES | Q43: 21603 E 11 MILE RD, SAINT CLAIR SHORES, Michigan | R43: Marcus Koss (3 ortho)
A44: Levan Internists | B44: 1972528818 | C44: PCP | D44: Tier 2 | E44: Ortho Referrer | F44: 50 | G44: 0 | H44: 2 | I44: 2 | J44: 2026-04-30 | K44: 2026-03-11 | L44: 127 | M44: 35.5 | N44: 21 | O44: C-D12 | P44: Livonia | Q44: 15130 Levan Rd, Livonia, MI, 48154 | R44: Talanki Viswanath, MD (2 ortho)
A45: Associated Orthopedists of Detroit-Shelby Township | B45: 59a078a4-145e-43bb-8052-a1ff32814d1e | C45: Orthopedic | D45: Tier 2 | E45: Ortho Referrer | F45: 49 | G45: 0 | H45: 1 | I45: 1 | J45: 2026-05-21 | K45: 2026-07-07 | L45: 9 | M45: 70 | N45: 21 | O45: C-D23 | P45: Shelby Township | Q45: 50505 Schoenherr Rd ste 120, Shelby Township, Michigan, 48315 | R45: Andrew Farris Ajluni, DO (1 ortho)
A46: Urgent Care Family | B46: 235de96a-2ae5-47a2-bf9a-8379e846684a | C46: Urgent Care | D46: Tier 2 | E46: Ortho Referrer | F46: 48 | G46: 0 | H46: 1 | I46: 1 | J46: 2026-06-23 | K46: 2026-06-25 | L46: 21 | M46: 18 | N46: 21 | O46: C-D01 | P46: Sterling Heights | Q46: 5843 17 Mile Road, Sterling Heights, Michigan, 48310 | R46: Lena Mansour, MD (1 ortho)
A47: Troy Primary Care | B47: e160ee5a-9916-41e2-b0c6-e2dae5007a6e | C47: PCP | D47: Tier 2 | E47: Ortho Referrer | F47: 48 | G47: 0 | H47: 1 | I47: 1 | J47: 2026-06-16 | K47: 2026-07-01 | L47: 15 | M47: 1 | N47: 21 | O47: C-D04 | P47: Troy | Q47: 1380 Coolidge Hwy suite 200, Troy, Michigan, 48084 | R47: Hadeel Kado, MD (1 ortho)
A48: Corewell Health Medical Group East | B48: 94e41be8-c824-4bbd-8119-47ffbb084071 | C48: PCP | D48: Tier 2 | E48: Ortho Referrer | F48: 48 | G48: 0 | H48: 1 | I48: 1 | J48: 2026-03-04 | K48: 2026-06-25 | L48: 21 | M48: 16 | N48: 21 | O48: C-D05 | P48: Roseville | Q48: 18325 E. 10 Mile Rd Suite 300, Roseville, MI, 48066 | R48: Deepali Jain, MD (1 ortho)
A49: Corewell Health Family Medicine -SAINT CLAIR SHORES | B49: a7f38558-5076-4a5b-9bd2-68b110ff29c1 | C49: PCP | D49: Tier 2 | E49: Ortho Referrer | F49: 48 | G49: 0 | H49: 1 | I49: 1 | J49: 2026-06-15 | K49: 2026-06-18 | L49: 28 | M49: 49 | N49: 21 | O49: C-D05 | P49: SAINT CLAIR SHORES | Q49: 25631 LITTLE MACK AVE STE 103, SAINT CLAIR SHORES, Michigan | R49: Sheena P Shah, MD (1 ortho)
...

Sheet Sean (verify)
A1: Account / Practice | B1: MMC Company ID | C1: Practice Type | D1: Tier | E1: Referral Evidence Band | F1: Target Score | G1: Spine 2026 | H1: Ortho 2026 | I1: Total B2B 2026 | J1: Last Spine Patient | K1: Last Completed Visit | L1: Days Since Visit | M1: Median Visit→Appt Lag | N1: Planned Cadence (d) | O1: Route Day | P1: City | Q1: Full Address | R1: Known Referring Providers | S1: Pre-Flag (auto) | T1: Disposition | U1: Final Practice Type | V1: Final Tier | W1: Spine Opportunity | X1: Employed Spine/Neuro Provider? | Y1: Competitor / Referral Restriction? | Z1: Recommended Cadence (d) | AA1: Removal / Reassignment Reason | AB1: PL Notes
A2: [EXAMPLE] Sample Family Medicine | B2: — | C2: PCP | D2: Tier 2 | E2: Ortho Referrer | F2: 48 | G2: 0 | H2: 3 | I2: 4 | K2: 2026-06-12 | L2: 39 | N2: 21 | O2: K-D03 | P2: Livonia | Q2: 123 Example Rd | R2: Dr. A. Sample (3 ortho) | T2: Keep | U2: PCP | V2: Tier 2 | W2: Medium | X2: No | Y2: No | Z2: 21 | AB2: Solid ortho sender; pitch spine pathway next visit
A3: Macomb Internal Medicine | B3: 5271bbd8-dfe5-4d54-a0a2-f5547050cafe | C3: PCP | D3: Tier 1 | E3: Repeat Spine Referrer | F3: 91 | G3: 4 | H3: 0 | I3: 4 | J3: 2026-07-08 | K3: 2026-07-10 | L3: 6 | M3: 9 | N3: 14 | O3: S-D01 | P3: Clinton Township | Q3: 15520 19 Mile Road, Suite 480, Clinton Township, MI, 48038 | R3: Anu Duvoor, MD (2 spine) · Linda Kosal, DO (2 spine)
A4: MI Family Practice | B4: 6aee51ce-625f-4968-96c5-5d9a6936bf27 | C4: PCP | D4: Tier 1 | E4: Repeat Spine Referrer | F4: 90 | G4: 3 | H4: 5 | I4: 8 | J4: 2026-07-07 | K4: 2026-07-09 | L4: 7 | M4: 28.5 | N4: 14 | O4: S-D02 | P4: Warren | Q4: 11300 E 13 Mile Rd, Suite 1, Warren, MI, 48093 | R4: Matthew Garza, DO (2 spine) · Taras Lisowsky, DO (1 spine)
A5: Ryan Medical Associates | B5: c88f05f1-5992-43b0-947c-469a44a0feef | C5: PCP | D5: Tier 1 | E5: Repeat Spine Referrer | F5: 82 | G5: 2 | H5: 1 | I5: 3 | J5: 2026-04-07 | K5: 2026-04-20 | L5: 87 | M5: 19 | N5: 14 | O5: S-D02 | P5: Warren | Q5: 21647 Ryan Rd, Warren, MI, 48091 | R5: Kevin A Agrest, DO (1 spine) · Christine England, NP (1 spine) · Jeffrey A Kraft, DO (1 ortho)
A6: Michigan Compassionate Care | B6: 33d0c0aa-7d47-450d-9673-71acb651321c | C6: PCP | D6: Tier 1 | E6: Repeat Spine Referrer | F6: 82 | G6: 2 | H6: 6 | I6: 9 | J6: 2026-05-11 | K6: 2026-03-11 | L6: 127 | M6: 21 | N6: 14 | O6: S-D02 | P6: Warren | Q6: 28401 Hoover, Warren, Michigan, 48093 | R6: Muhammad Vasiq, MD (2 spine) · Michigan Compassionate Care (2 ortho)
A7: Get Well Urgent Care Madison Heights | B7: 346a1335-a97f-4a1a-9847-77f9e71383c3 | C7: Urgent Care | D7: Tier 1 | E7: Repeat Spine Referrer | F7: 82 | G7: 2 | H7: 1 | I7: 3 | J7: 2026-06-24 | K7: 2026-03-25 | L7: 113 | M7: 28 | N7: 14 | O7: S-D03 | P7: Madison Heights | Q7: 350 E 12 Mile Rd, Madison Heights, Michigan, 48071 | R7: Get Well Urgent Care - Madison Heights (1 spine) · Getwell Urgent Care- Madison Heights (1 spine)
A8: Brigid Healthcare | B8: 63bf16ad-3645-45fb-8f1d-e1eb3a131efc | C8: PCP | D8: Tier 1 | E8: Repeat Spine Referrer | F8: 82 | G8: 2 | H8: 1 | I8: 3 | J8: 2026-04-17 | K8: 2026-04-14 | L8: 93 | M8: 10 | N8: 14 | O8: S-D03 | P8: Troy | Q8: 3456 Rochester Rd, Troy, Michigan, 48083 | R8: Hui Wang, PA (2 spine)
A9: Sterling Physicians | B9: 1972593499 | C9: PCP | D9: Tier 1 | E9: One Spine Patient | F9: 71 | G9: 1 | H9: 0 | I9: 1 | J9: 2026-07-07 | K9: 2026-06-04 | L9: 42 | M9: 33 | N9: 14 | O9: S-D03 | P9: Sterling Heights | Q9: 36040 Dequindre Road, Sterling Heights, Michigan, 48310 | R9: James Burtka, MD (1 spine)
A10: Michigan Primary Care - Sterling Heights | B10: ce3b56cf-1381-41d0-b067-752448464958 | C10: PCP | D10: Tier 1 | E10: One Spine Patient | F10: 70 | G10: 1 | H10: 0 | I10: 1 | J10: 2026-05-19 | K10: 2026-06-04 | L10: 42 | M10: 60 | N10: 14 | O10: S-D01 | P10: Sterling Heights | Q10: 41400 Dequindre Rd, ste 121, Sterling Heights, Michigan, 48314 | R10: Aleksandra Tasevski, NP (1 spine)
A11: Associates in Family Practice | B11: 1205856432 | C11: PCP | D11: Tier 1 | E11: One Spine Patient | F11: 70 | G11: 1 | H11: 1 | I11: 2 | J11: 2026-04-20 | K11: 2026-06-05 | L11: 41 | M11: 27 | N11: 14 | O11: S-D01 | P11: Sterling Heights | Q11: 42755 Mound Rd, Sterling Heights, Michigan, 48314 | R11: Fadi Oska, MD (1 spine)
A12: Schoenherr Parkway Family Practice | B12: 62e680e9-a222-400d-9186-a369d13cf23f | C12: PCP | D12: Tier 1 | E12: One Spine Patient | F12: 70 | G12: 1 | H12: 2 | I12: 3 | J12: 2026-04-01 | K12: 2026-04-29 | L12: 78 | M12: 40 | N12: 14 | O12: S-D01 | P12: Sterling Heights | Q12: 13951 Plumbrook, Sterling Heights, Michigan, 48312 | R12: Mona Khater, MD (1 spine)
A13: Get Well Urgent Care - Sterling Heights | B13: 1bcc2e23-5fc1-428c-ad41-dc35c5345bf7 | C13: Urgent Care | D13: Tier 1 | E13: One Spine Patient | F13: 70 | G13: 1 | H13: 1 | I13: 2 | J13: 2026-05-26 | K13: 2026-06-04 | L13: 42 | M13: 59 | N13: 14 | O13: S-D02 | P13: Sterling Heights | Q13: 2567 Metro Parkway, Sterling Heights, Michigan, 48310 | R13: Get Well Urgent Care Of Sterling Heights (1 spine) · Get Well Urgent Care - Sterling Heights (1 ortho)
A14: Kashat Urgent care | B14: 0b9485b1-39bd-4f21-8222-387834af8472 | C14: Urgent Care | D14: Tier 1 | E14: One Spine Patient | F14: 70 | G14: 1 | H14: 0 | I14: 1 | J14: 2026-06-03 | K14: 2026-06-04 | L14: 42 | M14: 75 | N14: 14 | O14: S-D03 | P14: Sterling Heights | Q14: 35200 Dequindre Road, Sterling Heights, Michigan, 48310 | R14: Ghazawan K Kashat, MD (1 spine)
... A28: Wattles Internal Medicine- use | B28: ea9682a6-09ea-4d32-a71d-171ffffb7847 | C28: PCP | D28: Tier 2 | E28: Ortho Referrer | F28: 46 | G28: 0 | H28: 1 | I28: 1 | J28: 2026-07-07 | K28: 2026-06-05 | L28: 41 | M28: 32 | N28: 21 | O28: S-D03 | P28: Troy | Q28: 1950 E Wattles Rd suite 101, Troy, Michigan, 48085 | R28: Mark Zohoury, DO (1 ortho)
A29: MyCare Health Center - Mt Clemens | B29: 1427049683 | C29: PCP | D29: Tier 2 | E29: Ortho Referrer | F29: 46 | G29: 0 | H29: 1 | I29: 1 | J29: 2026-04-27 | K29: 2026-05-14 | L29: 63 | M29: 84 | N29: 21 | O29: S-D04 | P29: Mount Clemens | Q29: 18 Market Street, ste C, Mount Clemens, MI, 48043 | R29: Christine M Allor Fnp-c (1 ortho) | S29: Medicaid-likely — verify payer
A30: Epic Health - St Clair Shores | B30: 8c04fb31-3380-488f-aa8a-954ff32146f2 | C30: PCP | D30: Tier 2 | E30: Ortho Referrer | F30: 46 | G30: 0 | H30: 1 | I30: 1 | J30: 2026-05-26 | K30: 2026-05-06 | L30: 71 | M30: 20 | N30: 21 | O30: S-D04 | P30: St. Clair Shores | Q30: 28001 Harper, St. Clair Shores, Michigan, 48081 | R30: Ronald Barnett, DO (1 ortho)
A31: Waypointe Internal Medicine | B31: 1164469821 | C31: PCP | D31: Tier 2 | E31: Ortho Referrer | F31: 46 | G31: 0 | H31: 1 | I31: 1 | J31: 2026-03-20 | K31: 2026-04-27 | L31: 80 | M31: 29 | N31: 21 | O31: S-D04 | P31: Saint Clair Shores | Q31: 24400 Greater Mack Ave, Saint Clair Shores, MI, 48080 | R31: Sara Ann Fox, MD (1 ortho)
A32: Sterling Medical Center & Urgent Care | B32: f30f611c-772a-406a-9d92-231790b785c2 | C32: Urgent Care | D32: Tier 2 | E32: Ortho Referrer | F32: 46 | G32: 0 | H32: 1 | I32: 1 | J32: 2026-04-20 | K32: 2026-04-30 | L32: 77 | M32: 73 | N32: 21 | O32: S-D04 | P32: STERLING HEIGHTS | Q32: 13409 E 14 MILE RD, STERLING HEIGHTS, Michigan, 48312 | R32: Mohammed Nader Bazzy (1 ortho)
A33: Toma & Yaldo Medical Center | B33: d1255d1a-17e8-4765-bfe5-45c6c087c8ed | C33: PCP | D33: Tier 2 | E33: Ortho Referrer | F33: 45 | G33: 0 | H33: 1 | I33: 1 | J33: 2026-07-07 | K33: 2026-03-18 | L33: 120 | M33: 111 | N33: 21 | O33: S-D01 | P33: Sterling Heights | Q33: 39150 Dequindre Rd suite 200, Sterling Heights, Michigan, 48310 | R33: Raad Toma, MD (1 ortho)
A34: Horizon Care Medical Group - Warren | B34: 476bc8e4-84c4-4063-97a9-b649ed44dddf | C34: PCP | D34: Tier 2 | E34: Ortho Referrer | F34: 45 | G34: 0 | H34: 1 | I34: 1 | J34: 2026-03-11 | K34: 2026-05-05 | L34: 72 | M34: 13 | N34: 21 | O34: S-D02 | P34: Warren | Q34: 26000 Hoover Rd #103, Warren, Michigan, 48089 | R34: Anthony Spearman, MD (1 ortho)
A35: South Lyon Family Docs | B35: 573750f7-b7bd-4246-b7ac-f1217823639f | C35: PCP | D35: Tier 2 | E35: Ortho Referrer | F35: 45 | G35: 0 | H35: 1 | I35: 1 | J35: 2026-05-20 | K35: 2026-03-04 | L35: 134 | M35: 77 | N35: 21 | O35: S-D03 | P35: South Lyon | Q35: 26006 Pontiac Trail, South Lyon, MI, 48178 | R35: Brandy Eberhardt, DO (1 ortho)
A36: Masonic Medical Center - Ascension | B36: e73f759b-87dc-444f-a504-b954ddeeace1 | C36: PCP | D36: Tier 2 | E36: Ortho Referrer | F36: 45 | G36: 0 | H36: 1 | I36: 1 | J36: 2026-05-15 | K36: 2026-03-27 | L36: 111 | M36: 49 | N36: 21 | O36: S-D04 | P36: St. Clair Shores | Q36: 21099 Masonic, St. Clair Shores, Michigan, 48082 | R36: Jeanette Elizabeth Wilson, MD (1 ortho)
A37: Aquino Integrative Internal Medicine | B37: 1780671461 | C37: PCP | D37: Tier 2 | E37: Ortho Referrer | F37: 45 | G37: 0 | H37: 1 | I37: 1 | J37: 2026-03-30 | K37: 2026-03-12 | L37: 126 | M37: 18 | N37: 21 | O37: S-D04 | P37: Roseville | Q37: 30695 Little Mack Avenue, ste 500, Roseville, Michigan, 48066 | R37: Robert Aquino, DO (1 ortho)
A38: Allied Internists | B38: 1063423176 | C38: PCP | D38: Tier 2 | E38: Ortho Referrer | F38: 45 | G38: 0 | H38: 1 | I38: 1 | J38: 2026-02-05 | K38: 2026-04-20 | L38: 87 | M38: 52 | N38: 21 | O38: S-D04 | P38: Roseville | Q38: 18263 E 10 Mile Rd, ste E, Roseville, Michigan, 48066 | R38: Wahed Ishaqsei, MD (1 ortho)
A39: Office of David Mandy DO | B39: da57adc9-a2cf-4705-886d-76146cbbde06 | C39: Pediatrics | D39: Tier 2 | E39: Ortho Referrer | F39: 44 | G39: 0 | H39: 1 | I39: 1 | J39: 2026-01-06 | K39: 2026-05-14 | L39: 63 | M39: 62 | N39: 21 | O39: S-D01 | P39: Macomb Township | Q39: 46600 Romeo Plank, Ste. 4, Macomb Township, MI, 48044 | R39: David Mandy (1 ortho) | S39: Pediatric (Jul 20 rule) → Review for removal
A40: Beaumont Family Medicine - Sterling Heights | B40: 1952519001 | C40: PCP | D40: Tier 3 | E40: Other Patient Referrer | F40: 23 | G40: 0 | H40: 0 | I40: 1 | J40: 2026-04-16 | K40: 2026-06-10 | L40: 36 | M40: 15 | N40: 30 | O40: S-D01 | P40: Sterling Heights | Q40: 44250 Dequindre, Sterling Heights, MI, 483141002 | R40: Hany Eraqi, MD
A41: Academic Internal Medicine (Ascension) | B41: 97ae4125-fd10-47de-8cae-c053e42232d0 | C41: PCP | D41: Tier 3 | E41: Other Patient Referrer | F41: 21 | G41: 0 | H41: 0 | I41: 1 | J41: 2026-04-16 | K41: 2026-03-17 | L41: 121 | M41: 30 | N41: 30 | O41: S-D01 | P41: Washington | Q41: 57850 Van Dyke Ave ste 600, Washington, Michigan, 48094 | R41: Zain Kulairi, MD
A42: Henry Ford Medical Center - Warren | B42: 1932273448 | C42: PCP | D42: Prospect | E42: Visit / Prospect | F42: 9 | G42: 0 | H42: 0 | I42: 0 | K42: 2026-05-26 | L42: 51 | N42: 45 | O42: S-D02 | P42: Warren | Q42: 8600 Chicago Road St, Warren, MI, 48093

Sheet Summary
B2: Validation Summary (auto-counts — fills as PLs disposition)
B4: PL | C4: Starting | D4: Keep | E4: Remove | F4: Reassign | G4: Not yet reviewed
B5: Kristen | C5: 180 | D5: =COUNTIF('Kristen'!$T$3:$T$400,"Keep") | E5: =COUNTIF('Kristen'!$T$3:$T$400,"Remove") | F5: =COUNTIF('Kristen'!$T$3:$T$400,"Reassign") | G5: =C5-SUM(D5:F5)
B6: Jasmine | C6: 310 | D6: =COUNTIF('Jasmine'!$T$3:$T$400,"Keep") | E6: =COUNTIF('Jasmine'!$T$3:$T$400,"Remove") | F6: =COUNTIF('Jasmine'!$T$3:$T$400,"Reassign") | G6: =C6-SUM(D6:F6)
B7: Coty | C7: 318 | D7: =COUNTIF('Coty'!$T$3:$T$400,"Keep") | E7: =COUNTIF('Coty'!$T$3:$T$400,"Remove") | F7: =COUNTIF('Coty'!$T$3:$T$400,"Reassign") | G7: =C7-SUM(D7:F7)
B8: Sean | C8: 40 | D8: =COUNTIF('Sean (verify)'!$T$3:$T$400,"Keep") | E8: =COUNTIF('Sean (verify)'!$T$3:$T$400,"Remove") | F8: =COUNTIF('Sean (verify)'!$T$3:$T$400,"Reassign") | G8: =C8-SUM(D8:F8)
B9: TOTAL | C9: =SUM(C5:C8) | D9: =SUM(D5:D8) | E9: =SUM(E5:E8) | F9: =SUM(F5:F8) | G9: =SUM(G5:G8)
B11: Deliver with the Jul 31 summary: accounts removed + reasons (filter Disposition=Remove) · reassignments · final tier/type mix · route days required (regenerated) · accounts needing >1 visit before Sep 30 (= all Final Tier 1 & 2).
